Workbook

Sheet Per-Trial Data
D1: Ligand #conf | G1: Ligand crg soln | J1: Ligand crg bound | M1: Apo-kinase charge | P1: Holo-kinase charge
A2: PDBID | B2: Ligand | C2: Kinase | D2: T01 | E2: T02 | F2: T03 | G2: T01 | H2: T02 | I2: T03 | J2: T01 | K2: T02 | L2: T03 | M2: T01 | N2: T02 | O2: T03 | P2: T01 | Q2: T02 | R2: T03
A3: 1XKK | B3: Lapatinib | C3: EGFR | D3: 4 | E3: 5 | F3: 4 | G3: 0.95 | H3: 0.95 | I3: 0.95 | J3: 0.52 | K3: 0.52 | L3: 0.53 | M3: 0.5 | N3: 0.54 | O3: 0.51 | P3: 0.68 | Q3: 0.75 | R3: 0.67
A4: 2EUF | B4: Palbociclib | C4: CDK6 | D4: 2 | E4: 2 | F4: 2 | G4: 0.98 | H4: 0.98 | I4: 0.98 | J4: 1 | K4: 1 | L4: 1 | M4: -8.87 | N4: -9.28 | O4: -9.75 | P4: -8.52 | Q4: -8.47 | R4: -8.93
A5: 2HYY | B5: Imatinib | C5: ABL | D5: 5 | E5: 5 | F5: 5 | G5: 0.97 | H5: 0.97 | I5: 0.97 | J5: 1 | K5: 1 | L5: 1 | M5: -6.16 | N5: -6.17 | O5: -6.19 | P5: -5.35 | Q5: -5.39 | R5: -5.38
A6: 2ITO | B6: Gefitinib | C6: EGFR | D6: 5 | E6: 5 | F6: 5 | G6: 0.3 | H6: 0.3 | I6: 0.3 | J6: 0.72 | K6: 0.77 | L6: 0.8 | M6: -7.14 | N6: -7.04 | O6: -7.1 | P6: -6.57 | Q6: -6.45 | R6: -6.52
A7: 2ITY | B7: Gefitinib | C7: EGFR | D7: 5 | E7: 5 | F7: 5 | G7: 0.3 | H7: 0.3 | I7: 0.3 | J7: 0.3 | K7: 0.34 | L7: 0.35 | M7: -6.04 | N7: -5.91 | O7: -6.03 | P7: -5.79 | Q7: -5.6 | R7: -5.77
A8: 2ITZ | B8: Gefitinib | C8: EGFR | D8: 5 | E8: 5 | F8: 5 | G8: 0.3 | H8: 0.3 | I8: 0.3 | J8: 0.64 | K8: 0.64 | L8: 0.66 | M8: -4.78 | N8: -4.77 | O8: -4.95 | P8: -4.25 | Q8: -4.23 | R8: -4.38
A9: 2WGJ | B9: Crizotinib | C9: MET | D9: 5 | E9: 4 | F9: 4 | G9: 1.61 | H9: 1.61 | I9: 1.61 | J9: 0.98 | K9: 0.97 | L9: 0.97 | M9: 6.97 | N9: 6.96 | O9: 7.05 | P9: 7.72 | Q9: 7.71 | R9: 7.78
A10: 2XP2 | B10: Crizotinib | C10: ALK | D10: 4 | E10: 4 | F10: 4 | G10: 1.61 | H10: 1.61 | I10: 1.61 | J10: 1 | K10: 1 | L10: 1 | M10: -5.9 | N10: -5.91 | O10: -5.92 | P10: -4.97 | Q10: -5 | R10: -4.99
A11: 2YFX | B11: Crizotinib | C11: ALK | D11: 5 | E11: 4 | F11: 4 | G11: 1.61 | H11: 1.61 | I11: 1.61 | J11: 1 | K11: 1 | L11: 1 | M11: -4.66 | N11: -4.63 | O11: -4.59 | P11: -3.64 | Q11: -3.67 | R11: -3.61
A12: 3AOX | B12: Alectinib | C12: ALK | D12: 2 | E12: 2 | F12: 3 | G12: 0.56 | H12: 0.56 | I12: 0.56 | J12: 0.9 | K12: 0.79 | L12: 0.79 | M12: -8.38 | N12: -8.45 | O12: -8.36 | P12: -7.5 | Q12: -7.68 | R12: -7.63
A13: 3CS9 | B13: Nilotinib | C13: ABL | D13: 3 | E13: 3 | F13: 4 | G13: 0.09 | H13: 0.09 | I13: 0.09 | J13: 0.17 | K13: 0.61 | L13: 0.19 | M13: -4.58 | N13: -4.6 | O13: -4.61 | P13: -4.39 | Q13: -4.03 | R13: -4.42
A14: 3LXK | B14: Tofacitinib | C14: JAK3 | D14: 5 | E14: 5 | F14: 5 | G14: 0.03 | H14: 0.03 | I14: 0.03 | J14: 0.03 | K14: 0.07 | L14: 0.05 | M14: 1.1 | N14: 1.26 | O14: 1.1 | P14: 1.23 | Q14: 1.39 | R14: 1.22
... A39: 5MO4 | B39: Nilotinib | C39: ABL | D39: 3 | E39: 3 | F39: 3 | G39: 0.09 | H39: 0.09 | I39: 0.09 | J39: 0.48 | K39: 0.21 | L39: 0.25 | M39: -8.04 | N39: -8.08 | O39: -7.95 | P39: -7.63 | Q39: -7.86 | R39: -7.71
A41: Source: xts_sum_crg.out (pH 7.4, entropy-corrected by xts_corr.py) in each trial's run_inhib / run_holo / run_apo; #conf from run_inhib/head3.lst. These are the workbook's only hardcoded values.

Sheet Table 1 (Trials)
A1: Table 1 (Trials): inhibitor and kinase charge at pH 7.4, mean of 3 independent trials
A2: Each value is the mean over the trials; ± columns are the standard error of the mean (SD/√n). See the Methods sheet.
D4: Ligand | E4: Ligand | F4: Ligand | G4: Ligand | H4: Ligand | I4: Ligand | J4: Apo-kinase | K4: Apo-kinase | L4: Holo-kinase | M4: Holo-kinase | N4: Holo-Apo | O4: Holo-Apo
A5: PDBID | B5: Ligand | C5: Kinase | D5: #conf | E5: crg soln | F5: ± SEM | G5: crg bound | H5: ± SEM | I5: ∆crg | J5: ± SEM | K5: charge | L5: ± SEM | M5: charge | N5: ± SEM | O5: ∆crg | P5: ± SEM
B6: ABL
A7: 2HYY | B7: Imatinib | C7: ABL | D7: =AVERAGE('Per-Trial Data'!$D5:$F5) | E7: =AVERAGE('Per-Trial Data'!$G5:$I5) | F7: =IF(COUNT('Per-Trial Data'!$G5:$I5)>1,STDEV('Per-Trial Data'!$G5:$I5)/SQRT(COUNT('Per-Trial Data'!$G5:$I5)),0) | G7: =AVERAGE('Per-Trial Data'!$J5:$L5) | H7: =IF(COUNT('Per-Trial Data'!$J5:$L5)>1,STDEV('Per-Trial Data'!$J5:$L5)/SQRT(COUNT('Per-Trial Data'!$J5:$L5)),0) | I7: =G7-E7 | J7: =SQRT(F7^2+H7^2) | K7: =AVERAGE('Per-Trial Data'!$M5:$O5) | L7: =IF(COUNT('Per-Trial Data'!$M5:$O5)>1,STDEV('Per-Trial Data'!$M5:$O5)/SQRT(COUNT('Per-Trial Data'!$M5:$O5)),0) | M7: =AVERAGE('Per-Trial Data'!$P5:$R5) | N7: =IF(COUNT('Per-Trial Data'!$P5:$R5)>1,STDEV('Per-Trial Data'!$P5:$R5)/SQRT(COUNT('Per-Trial Data'!$P5:$R5)),0) | O7: =M7-K7 | P7: =SQRT(L7^2+N7^2)
A8: 3CS9 | B8: Nilotinib | C8: ABL | D8: =AVERAGE('Per-Trial Data'!$D13:$F13) | E8: =AVERAGE('Per-Trial Data'!$G13:$I13) | F8: =IF(COUNT('Per-Trial Data'!$G13:$I13)>1,STDEV('Per-Trial Data'!$G13:$I13)/SQRT(COUNT('Per-Trial Data'!$G13:$I13)),0) | G8: =AVERAGE('Per-Trial Data'!$J13:$L13) | H8: =IF(COUNT('Per-Trial Data'!$J13:$L13)>1,STDEV('Per-Trial Data'!$J13:$L13)/SQRT(COUNT('Per-Trial Data'!$J13:$L13)),0) | I8: =G8-E8 | J8: =SQRT(F8^2+H8^2) | K8: =AVERAGE('Per-Trial Data'!$M13:$O13) | L8: =IF(COUNT('Per-Trial Data'!$M13:$O13)>1,STDEV('Per-Trial Data'!$M13:$O13)/SQRT(COUNT('Per-Trial Data'!$M13:$O13)),0) | M8: =AVERAGE('Per-Trial Data'!$P13:$R13) | N8: =IF(COUNT('Per-Trial Data'!$P13:$R13)>1,STDEV('Per-Trial Data'!$P13:$R13)/SQRT(COUNT('Per-Trial Data'!$P13:$R13)),0) | O8: =M8-K8 | P8: =SQRT(L8^2+N8^2)
A9: 3PYY | B9: Imatinib | C9: ABL | D9: =AVERAGE('Per-Trial Data'!$D15:$F15) | E9: =AVERAGE('Per-Trial Data'!$G15:$I15) | F9: =IF(COUNT('Per-Trial Data'!$G15:$I15)>1,STDEV('Per-Trial Data'!$G15:$I15)/SQRT(COUNT('Per-Trial Data'!$G15:$I15)),0) | G9: =AVERAGE('Per-Trial Data'!$J15:$L15) | H9: =IF(COUNT('Per-Trial Data'!$J15:$L15)>1,STDEV('Per-Trial Data'!$J15:$L15)/SQRT(COUNT('Per-Trial Data'!$J15:$L15)),0) | I9: =G9-E9 | J9: =SQRT(F9^2+H9^2) | K9: =AVERAGE('Per-Trial Data'!$M15:$O15) | L9: =IF(COUNT('Per-Trial Data'!$M15:$O15)>1,STDEV('Per-Trial Data'!$M15:$O15)/SQRT(COUNT('Per-Trial Data'!$M15:$O15)),0) | M9: =AVERAGE('Per-Trial Data'!$P15:$R15) | N9: =IF(COUNT('Per-Trial Data'!$P15:$R15)>1,STDEV('Per-Trial Data'!$P15:$R15)/SQRT(COUNT('Per-Trial Data'!$P15:$R15)),0) | O9: =M9-K9 | P9: =SQRT(L9^2+N9^2)
A10: 3UE4 | B10: Bosutinib | C10: ABL | D10: =AVERAGE('Per-Trial Data'!$D16:$F16) | E10: =AVERAGE('Per-Trial Data'!$G16:$I16) | F10: =IF(COUNT('Per-Trial Data'!$G16:$I16)>1,STDEV('Per-Trial Data'!$G16:$I16)/SQRT(COUNT('Per-Trial Data'!$G16:$I16)),0) | G10: =AVERAGE('Per-Trial Data'!$J16:$L16) | H10: =IF(COUNT('Per-Trial Data'!$J16:$L16)>1,STDEV('Per-Trial Data'!$J16:$L16)/SQRT(COUNT('Per-Trial Data'!$J16:$L16)),0) | I10: =G10-E10 | J10: =SQRT(F10^2+H10^2) | K10: =AVERAGE('Per-Trial Data'!$M16:$O16) | L10: =IF(COUNT('Per-Trial Data'!$M16:$O16)>1,STDEV('Per-Trial Data'!$M16:$O16)/SQRT(COUNT('Per-Trial Data'!$M16:$O16)),0) | M10: =AVERAGE('Per-Trial Data'!$P16:$R16) | N10: =IF(COUNT('Per-Trial Data'!$P16:$R16)>1,STDEV('Per-Trial Data'!$P16:$R16)/SQRT(COUNT('Per-Trial Data'!$P16:$R16)),0) | O10: =M10-K10 | P10: =SQRT(L10^2+N10^2)
A11: 5MO4 | B11: Nilotinib | C11: ABL | D11: =AVERAGE('Per-Trial Data'!$D39:$F39) | E11: =AVERAGE('Per-Trial Data'!$G39:$I39) | F11: =IF(COUNT('Per-Trial Data'!$G39:$I39)>1,STDEV('Per-Trial Data'!$G39:$I39)/SQRT(COUNT('Per-Trial Data'!$G39:$I39)),0) | G11: =AVERAGE('Per-Trial Data'!$J39:$L39) | H11: =IF(COUNT('Per-Trial Data'!$J39:$L39)>1,STDEV('Per-Trial Data'!$J39:$L39)/SQRT(COUNT('Per-Trial Data'!$J39:$L39)),0) | I11: =G11-E11 | J11: =SQRT(F11^2+H11^2) | K11: =AVERAGE('Per-Trial Data'!$M39:$O39) | L11: =IF(COUNT('Per-Trial Data'!$M39:$O39)>1,STDEV('Per-Trial Data'!$M39:$O39)/SQRT(COUNT('Per-Trial Data'!$M39:$O39)),0) | M11: =AVERAGE('Per-Trial Data'!$P39:$R39) | N11: =IF(COUNT('Per-Trial Data'!$P39:$R39)>1,STDEV('Per-Trial Data'!$P39:$R39)/SQRT(COUNT('Per-Trial Data'!$P39:$R39)),0) | O11: =M11-K11 | P11: =SQRT(L11^2+N11^2)
B12: ALK
A13: 2XP2 | B13: Crizotinib | C13: ALK | D13: =AVERAGE('Per-Trial Data'!$D10:$F10) | E13: =AVERAGE('Per-Trial Data'!$G10:$I10) | F13: =IF(COUNT('Per-Trial Data'!$G10:$I10)>1,STDEV('Per-Trial Data'!$G10:$I10)/SQRT(COUNT('Per-Trial Data'!$G10:$I10)),0) | G13: =AVERAGE('Per-Trial Data'!$J10:$L10) | H13: =IF(COUNT('Per-Trial Data'!$J10:$L10)>1,STDEV('Per-Trial Data'!$J10:$L10)/SQRT(COUNT('Per-Trial Data'!$J10:$L10)),0) | I13: =G13-E13 | J13: =SQRT(F13^2+H13^2) | K13: =AVERAGE('Per-Trial Data'!$M10:$O10) | L13: =IF(COUNT('Per-Trial Data'!$M10:$O10)>1,STDEV('Per-Trial Data'!$M10:$O10)/SQRT(COUNT('Per-Trial Data'!$M10:$O10)),0) | M13: =AVERAGE('Per-Trial Data'!$P10:$R10) | N13: =IF(COUNT('Per-Trial Data'!$P10:$R10)>1,STDEV('Per-Trial Data'!$P10:$R10)/SQRT(COUNT('Per-Trial Data'!$P10:$R10)),0) | O13: =M13-K13 | P13: =SQRT(L13^2+N13^2)
A14: 2YFX | B14: Crizotinib | C14: ALK | D14: =AVERAGE('Per-Trial Data'!$D11:$F11) | E14: =AVERAGE('Per-Trial Data'!$G11:$I11) | F14: =IF(COUNT('Per-Trial Data'!$G11:$I11)>1,STDEV('Per-Trial Data'!$G11:$I11)/SQRT(COUNT('Per-Trial Data'!$G11:$I11)),0) | G14: =AVERAGE('Per-Trial Data'!$J11:$L11) | H14: =IF(COUNT('Per-Trial Data'!$J11:$L11)>1,STDEV('Per-Trial Data'!$J11:$L11)/SQRT(COUNT('Per-Trial Data'!$J11:$L11)),0) | I14: =G14-E14 | J14: =SQRT(F14^2+H14^2) | K14: =AVERAGE('Per-Trial Data'!$M11:$O11) | L14: =IF(COUNT('Per-Trial Data'!$M11:$O11)>1,STDEV('Per-Trial Data'!$M11:$O11)/SQRT(COUNT('Per-Trial Data'!$M11:$O11)),0) | M14: =AVERAGE('Per-Trial Data'!$P11:$R11) | N14: =IF(COUNT('Per-Trial Data'!$P11:$R11)>1,STDEV('Per-Trial Data'!$P11:$R11)/SQRT(COUNT('Per-Trial Data'!$P11:$R11)),0) | O14: =M14-K14 | P14: =SQRT(L14^2+N14^2)
A15: 3AOX | B15: Alectinib | C15: ALK | D15: =AVERAGE('Per-Trial Data'!$D12:$F12) | E15: =AVERAGE('Per-Trial Data'!$G12:$I12) | F15: =IF(COUNT('Per-Trial Data'!$G12:$I12)>1,STDEV('Per-Trial Data'!$G12:$I12)/SQRT(COUNT('Per-Trial Data'!$G12:$I12)),0) | G15: =AVERAGE('Per-Trial Data'!$J12:$L12) | H15: =IF(COUNT('Per-Trial Data'!$J12:$L12)>1,STDEV('Per-Trial Data'!$J12:$L12)/SQRT(COUNT('Per-Trial Data'!$J12:$L12)),0) | I15: =G15-E15 | J15: =SQRT(F15^2+H15^2) | K15: =AVERAGE('Per-Trial Data'!$M12:$O12) | L15: =IF(COUNT('Per-Trial Data'!$M12:$O12)>1,STDEV('Per-Trial Data'!$M12:$O12)/SQRT(COUNT('Per-Trial Data'!$M12:$O12)),0) | M15: =AVERAGE('Per-Trial Data'!$P12:$R12) | N15: =IF(COUNT('Per-Trial Data'!$P12:$R12)>1,STDEV('Per-Trial Data'!$P12:$R12)/SQRT(COUNT('Per-Trial Data'!$P12:$R12)),0) | O15: =M15-K15 | P15: =SQRT(L15^2+N15^2)
A16: 4ANQ | B16: Crizotinib | C16: ALK | D16: =AVERAGE('Per-Trial Data'!$D25:$F25) | E16: =AVERAGE('Per-Trial Data'!$G25:$I25) | F16: =IF(COUNT('Per-Trial Data'!$G25:$I25)>1,STDEV('Per-Trial Data'!$G25:$I25)/SQRT(COUNT('Per-Trial Data'!$G25:$I25)),0) | G16: =AVERAGE('Per-Trial Data'!$J25:$L25) | H16: =IF(COUNT('Per-Trial Data'!$J25:$L25)>1,STDEV('Per-Trial Data'!$J25:$L25)/SQRT(COUNT('Per-Trial Data'!$J25:$L25)),0) | I16: =G16-E16 | J16: =SQRT(F16^2+H16^2) | K16: =AVERAGE('Per-Trial Data'!$M25:$O25) | L16: =IF(COUNT('Per-Trial Data'!$M25:$O25)>1,STDEV('Per-Trial Data'!$M25:$O25)/SQRT(COUNT('Per-Trial Data'!$M25:$O25)),0) | M16: =AVERAGE('Per-Trial Data'!$P25:$R25) | N16: =IF(COUNT('Per-Trial Data'!$P25:$R25)>1,STDEV('Per-Trial Data'!$P25:$R25)/SQRT(COUNT('Per-Trial Data'!$P25:$R25)),0) | O16: =M16-K16 | P16: =SQRT(L16^2+N16^2)
A17: 4ANS | B17: Crizotinib | C17: ALK | D17: =AVERAGE('Per-Trial Data'!$D26:$F26) | E17: =AVERAGE('Per-Trial Data'!$G26:$I26) | F17: =IF(COUNT('Per-Trial Data'!$G26:$I26)>1,STDEV('Per-Trial Data'!$G26:$I26)/SQRT(COUNT('Per-Trial Data'!$G26:$I26)),0) | G17: =AVERAGE('Per-Trial Data'!$J26:$L26) | H17: =IF(COUNT('Per-Trial Data'!$J26:$L26)>1,STDEV('Per-Trial Data'!$J26:$L26)/SQRT(COUNT('Per-Trial Data'!$J26:$L26)),0) | I17: =G17-E17 | J17: =SQRT(F17^2+H17^2) | K17: =AVERAGE('Per-Trial Data'!$M26:$O26) | L17: =IF(COUNT('Per-Trial Data'!$M26:$O26)>1,STDEV('Per-Trial Data'!$M26:$O26)/SQRT(COUNT('Per-Trial Data'!$M26:$O26)),0) | M17: =AVERAGE('Per-Trial Data'!$P26:$R26) | N17: =IF(COUNT('Per-Trial Data'!$P26:$R26)>1,STDEV('Per-Trial Data'!$P26:$R26)/SQRT(COUNT('Per-Trial Data'!$P26:$R26)),0) | O17: =M17-K17 | P17: =SQRT(L17^2+N17^2)
A18: 4MKC | B18: Ceritinib | C18: ALK | D18: =AVERAGE('Per-Trial Data'!$D32:$F32) | E18: =AVERAGE('Per-Trial Data'!$G32:$I32) | F18: =IF(COUNT('Per-Trial Data'!$G32:$I32)>1,STDEV('Per-Trial Data'!$G32:$I32)/SQRT(COUNT('Per-Trial Data'!$G32:$I32)),0) | G18: =AVERAGE('Per-Trial Data'!$J32:$L32) | H18: =IF(COUNT('Per-Trial Data'!$J32:$L32)>1,STDEV('Per-Trial Data'!$J32:$L32)/SQRT(COUNT('Per-Trial Data'!$J32:$L32)),0) | I18: =G18-E18 | J18: =SQRT(F18^2+H18^2) | K18: =AVERAGE('Per-Trial Data'!$M32:$O32) | L18: =IF(COUNT('Per-Trial Data'!$M32:$O32)>1,STDEV('Per-Trial Data'!$M32:$O32)/SQRT(COUNT('Per-Trial Data'!$M32:$O32)),0) | M18: =AVERAGE('Per-Trial Data'!$P32:$R32) | N18: =IF(COUNT('Per-Trial Data'!$P32:$R32)>1,STDEV('Per-Trial Data'!$P32:$R32)/SQRT(COUNT('Per-Trial Data'!$P32:$R32)),0) | O18: =M18-K18 | P18: =SQRT(L18^2+N18^2)
A19: 5AAA | B19: Crizotinib | C19: ALK | D19: =AVERAGE('Per-Trial Data'!$D35:$F35) | E19: =AVERAGE('Per-Trial Data'!$G35:$I35) | F19: =IF(COUNT('Per-Trial Data'!$G35:$I35)>1,STDEV('Per-Trial Data'!$G35:$I35)/SQRT(COUNT('Per-Trial Data'!$G35:$I35)),0) | G19: =AVERAGE('Per-Trial Data'!$J35:$L35) | H19: =IF(COUNT('Per-Trial Data'!$J35:$L35)>1,STDEV('Per-Trial Data'!$J35:$L35)/SQRT(COUNT('Per-Trial Data'!$J35:$L35)),0) | I19: =G19-E19 | J19: =SQRT(F19^2+H19^2) | K19: =AVERAGE('Per-Trial Data'!$M35:$O35) | L19: =IF(COUNT('Per-Trial Data'!$M35:$O35)>1,STDEV('Per-Trial Data'!$M35:$O35)/SQRT(COUNT('Per-Trial Data'!$M35:$O35)),0) | M19: =AVERAGE('Per-Trial Data'!$P35:$R35) | N19: =IF(COUNT('Per-Trial Data'!$P35:$R35)>1,STDEV('Per-Trial Data'!$P35:$R35)/SQRT(COUNT('Per-Trial Data'!$P35:$R35)),0) | O19: =M19-K19 | P19: =SQRT(L19^2+N19^2)
A20: 5AAB | B20: Crizotinib | C20: ALK | D20: =AVERAGE('Per-Trial Data'!$D36:$F36) | E20: =AVERAGE('Per-Trial Data'!$G36:$I36) | F20: =IF(COUNT('Per-Trial Data'!$G36:$I36)>1,STDEV('Per-Trial Data'!$G36:$I36)/SQRT(COUNT('Per-Trial Data'!$G36:$I36)),0) | G20: =AVERAGE('Per-Trial Data'!$J36:$L36) | H20: =IF(COUNT('Per-Trial Data'!$J36:$L36)>1,STDEV('Per-Trial Data'!$J36:$L36)/SQRT(COUNT('Per-Trial Data'!$J36:$L36)),0) | I20: =G20-E20 | J20: =SQRT(F20^2+H20^2) | K20: =AVERAGE('Per-Trial Data'!$M36:$O36) | L20: =IF(COUNT('Per-Trial Data'!$M36:$O36)>1,STDEV('Per-Trial Data'!$M36:$O36)/SQRT(COUNT('Per-Trial Data'!$M36:$O36)),0) | M20: =AVERAGE('Per-Trial Data'!$P36:$R36) | N20: =IF(COUNT('Per-Trial Data'!$P36:$R36)>1,STDEV('Per-Trial Data'!$P36:$R36)/SQRT(COUNT('Per-Trial Data'!$P36:$R36)),0) | O20: =M20-K20 | P20: =SQRT(L20^2+N20^2)
A21: 5AAC | B21: Crizotinib | C21: ALK | D21: =AVERAGE('Per-Trial Data'!$D37:$F37) | E21: =AVERAGE('Per-Trial Data'!$G37:$I37) | F21: =IF(COUNT('Per-Trial Data'!$G37:$I37)>1,STDEV('Per-Trial Data'!$G37:$I37)/SQRT(COUNT('Per-Trial Data'!$G37:$I37)),0) | G21: =AVERAGE('Per-Trial Data'!$J37:$L37) | H21: =IF(COUNT('Per-Trial Data'!$J37:$L37)>1,STDEV('Per-Trial Data'!$J37:$L37)/SQRT(COUNT('Per-Trial Data'!$J37:$L37)),0) | I21: =G21-E21 | J21: =SQRT(F21^2+H21^2) | K21: =AVERAGE('Per-Trial Data'!$M37:$O37) | L21: =IF(COUNT('Per-Trial Data'!$M37:$O37)>1,STDEV('Per-Trial Data'!$M37:$O37)/SQRT(COUNT('Per-Trial Data'!$M37:$O37)),0) | M21: =AVERAGE('Per-Trial Data'!$P37:$R37) | N21: =IF(COUNT('Per-Trial Data'!$P37:$R37)>1,STDEV('Per-Trial Data'!$P37:$R37)/SQRT(COUNT('Per-Trial Data'!$P37:$R37)),0) | O21: =M21-K21 | P21: =SQRT(L21^2+N21^2)
B22: CDK6
A23: 2EUF | B23: Palbociclib | C23: CDK6 | D23: =AVERAGE('Per-Trial Data'!$D4:$F4) | E23: =AVERAGE('Per-Trial Data'!$G4:$I4) | F23: =IF(COUNT('Per-Trial Data'!$G4:$I4)>1,STDEV('Per-Trial Data'!$G4:$I4)/SQRT(COUNT('Per-Trial Data'!$G4:$I4)),0) | G23: =AVERAGE('Per-Trial Data'!$J4:$L4) | H23: =IF(COUNT('Per-Trial Data'!$J4:$L4)>1,STDEV('Per-Trial Data'!$J4:$L4)/SQRT(COUNT('Per-Trial Data'!$J4:$L4)),0) | I23: =G23-E23 | J23: =SQRT(F23^2+H23^2) | K23: =AVERAGE('Per-Trial Data'!$M4:$O4) | L23: =IF(COUNT('Per-Trial Data'!$M4:$O4)>1,STDEV('Per-Trial Data'!$M4:$O4)/SQRT(COUNT('Per-Trial Data'!$M4:$O4)),0) | M23: =AVERAGE('Per-Trial Data'!$P4:$R4) | N23: =IF(COUNT('Per-Trial Data'!$P4:$R4)>1,STDEV('Per-Trial Data'!$P4:$R4)/SQRT(COUNT('Per-Trial Data'!$P4:$R4)),0) | O23: =M23-K23 | P23: =SQRT(L23^2+N23^2)
A24: 5L2I | B24: Palbociclib | C24: CDK6 | D24: =AVERAGE('Per-Trial Data'!$D38:$F38) | E24: =AVERAGE('Per-Trial Data'!$G38:$I38) | F24: =IF(COUNT('Per-Trial Data'!$G38:$I38)>1,STDEV('Per-Trial Data'!$G38:$I38)/SQRT(COUNT('Per-Trial Data'!$G38:$I38)),0) | G24: =AVERAGE('Per-Trial Data'!$J38:$L38) | H24: =IF(COUNT('Per-Trial Data'!$J38:$L38)>1,STDEV('Per-Trial Data'!$J38:$L38)/SQRT(COUNT('Per-Trial Data'!$J38:$L38)),0) | I24: =G24-E24 | J24: =SQRT(F24^2+H24^2) | K24: =AVERAGE('Per-Trial Data'!$M38:$O38) | L24: =IF(COUNT('Per-Trial Data'!$M38:$O38)>1,STDEV('Per-Trial Data'!$M38:$O38)/SQRT(COUNT('Per-Trial Data'!$M38:$O38)),0) | M24: =AVERAGE('Per-Trial Data'!$P38:$R38) | N24: =IF(COUNT('Per-Trial Data'!$P38:$R38)>1,STDEV('Per-Trial Data'!$P38:$R38)/SQRT(COUNT('Per-Trial Data'!$P38:$R38)),0) | O24: =M24-K24 | P24: =SQRT(L24^2+N24^2)
B25: DDR1
A26: 3ZOS | B26: Ponatinib | C26: DDR1 | D26: =AVERAGE('Per-Trial Data'!$D20:$F20) | E26: =AVERAGE('Per-Trial Data'!$G20:$I20) | F26: =IF(COUNT('Per-Trial Data'!$G20:$I20)>1,STDEV('Per-Trial Data'!$G20:$I20)/SQRT(COUNT('Per-Trial Data'!$G20:$I20)),0) | G26: =AVERAGE('Per-Trial Data'!$J20:$L20) | H26: =IF(COUNT('Per-Trial Data'!$J20:$L20)>1,STDEV('Per-Trial Data'!$J20:$L20)/SQRT(COUNT('Per-Trial Data'!$J20:$L20)),0) | I26: =G26-E26 | J26: =SQRT(F26^2+H26^2) | K26: =AVERAGE('Per-Trial Data'!$M20:$O20) | L26: =IF(COUNT('Per-Trial Data'!$M20:$O20)>1,STDEV('Per-Trial Data'!$M20:$O20)/SQRT(COUNT('Per-Trial Data'!$M20:$O20)),0) | M26: =AVERAGE('Per-Trial Data'!$P20:$R20) | N26: =IF(COUNT('Per-Trial Data'!$P20:$R20)>1,STDEV('Per-Trial Data'!$P20:$R20)/SQRT(COUNT('Per-Trial Data'!$P20:$R20)),0) | O26: =M26-K26 | P26: =SQRT(L26^2+N26^2)
B27: EGFR
A28: 1XKK | B28: Lapatinib | C28: EGFR | D28: =AVERAGE('Per-Trial Data'!$D3:$F3) | E28: =AVERAGE('Per-Trial Data'!$G3:$I3) | F28: =IF(COUNT('Per-Trial Data'!$G3:$I3)>1,STDEV('Per-Trial Data'!$G3:$I3)/SQRT(COUNT('Per-Trial Data'!$G3:$I3)),0) | G28: =AVERAGE('Per-Trial Data'!$J3:$L3) | H28: =IF(COUNT('Per-Trial Data'!$J3:$L3)>1,STDEV('Per-Trial Data'!$J3:$L3)/SQRT(COUNT('Per-Trial Data'!$J3:$L3)),0) | I28: =G28-E28 | J28: =SQRT(F28^2+H28^2) | K28: =AVERAGE('Per-Trial Data'!$M3:$O3) | L28: =IF(COUNT('Per-Trial Data'!$M3:$O3)>1,STDEV('Per-Trial Data'!$M3:$O3)/SQRT(COUNT('Per-Trial Data'!$M3:$O3)),0) | M28: =AVERAGE('Per-Trial Data'!$P3:$R3) | N28: =IF(COUNT('Per-Trial Data'!$P3:$R3)>1,STDEV('Per-Trial Data'!$P3:$R3)/SQRT(COUNT('Per-Trial Data'!$P3:$R3)),0) | O28: =M28-K28 | P28: =SQRT(L28^2+N28^2)
A29: 2ITO | B29: Gefitinib | C29: EGFR | D29: =AVERAGE('Per-Trial Data'!$D6:$F6) | E29: =AVERAGE('Per-Trial Data'!$G6:$I6) | F29: =IF(COUNT('Per-Trial Data'!$G6:$I6)>1,STDEV('Per-Trial Data'!$G6:$I6)/SQRT(COUNT('Per-Trial Data'!$G6:$I6)),0) | G29: =AVERAGE('Per-Trial Data'!$J6:$L6) | H29: =IF(COUNT('Per-Trial Data'!$J6:$L6)>1,STDEV('Per-Trial Data'!$J6:$L6)/SQRT(COUNT('Per-Trial Data'!$J6:$L6)),0) | I29: =G29-E29 | J29: =SQRT(F29^2+H29^2) | K29: =AVERAGE('Per-Trial Data'!$M6:$O6) | L29: =IF(COUNT('Per-Trial Data'!$M6:$O6)>1,STDEV('Per-Trial Data'!$M6:$O6)/SQRT(COUNT('Per-Trial Data'!$M6:$O6)),0) | M29: =AVERAGE('Per-Trial Data'!$P6:$R6) | N29: =IF(COUNT('Per-Trial Data'!$P6:$R6)>1,STDEV('Per-Trial Data'!$P6:$R6)/SQRT(COUNT('Per-Trial Data'!$P6:$R6)),0) | O29: =M29-K29 | P29: =SQRT(L29^2+N29^2)
A30: 2ITY | B30: Gefitinib | C30: EGFR | D30: =AVERAGE('Per-Trial Data'!$D7:$F7) | E30: =AVERAGE('Per-Trial Data'!$G7:$I7) | F30: =IF(COUNT('Per-Trial Data'!$G7:$I7)>1,STDEV('Per-Trial Data'!$G7:$I7)/SQRT(COUNT('Per-Trial Data'!$G7:$I7)),0) | G30: =AVERAGE('Per-Trial Data'!$J7:$L7) | H30: =IF(COUNT('Per-Trial Data'!$J7:$L7)>1,STDEV('Per-Trial Data'!$J7:$L7)/SQRT(COUNT('Per-Trial Data'!$J7:$L7)),0) | I30: =G30-E30 | J30: =SQRT(F30^2+H30^2) | K30: =AVERAGE('Per-Trial Data'!$M7:$O7) | L30: =IF(COUNT('Per-Trial Data'!$M7:$O7)>1,STDEV('Per-Trial Data'!$M7:$O7)/SQRT(COUNT('Per-Trial Data'!$M7:$O7)),0) | M30: =AVERAGE('Per-Trial Data'!$P7:$R7) | N30: =IF(COUNT('Per-Trial Data'!$P7:$R7)>1,STDEV('Per-Trial Data'!$P7:$R7)/SQRT(COUNT('Per-Trial Data'!$P7:$R7)),0) | O30: =M30-K30 | P30: =SQRT(L30^2+N30^2)
A31: 2ITZ | B31: Gefitinib | C31: EGFR | D31: =AVERAGE('Per-Trial Data'!$D8:$F8) | E31: =AVERAGE('Per-Trial Data'!$G8:$I8) | F31: =IF(COUNT('Per-Trial Data'!$G8:$I8)>1,STDEV('Per-Trial Data'!$G8:$I8)/SQRT(COUNT('Per-Trial Data'!$G8:$I8)),0) | G31: =AVERAGE('Per-Trial Data'!$J8:$L8) | H31: =IF(COUNT('Per-Trial Data'!$J8:$L8)>1,STDEV('Per-Trial Data'!$J8:$L8)/SQRT(COUNT('Per-Trial Data'!$J8:$L8)),0) | I31: =G31-E31 | J31: =SQRT(F31^2+H31^2) | K31: =AVERAGE('Per-Trial Data'!$M8:$O8) | L31: =IF(COUNT('Per-Trial Data'!$M8:$O8)>1,STDEV('Per-Trial Data'!$M8:$O8)/SQRT(COUNT('Per-Trial Data'!$M8:$O8)),0) | M31: =AVERAGE('Per-Trial Data'!$P8:$R8) | N31: =IF(COUNT('Per-Trial Data'!$P8:$R8)>1,STDEV('Per-Trial Data'!$P8:$R8)/SQRT(COUNT('Per-Trial Data'!$P8:$R8)),0) | O31: =M31-K31 | P31: =SQRT(L31^2+N31^2)
A32: 3UG2 | B32: Gefitinib | C32: EGFR | D32: =AVERAGE('Per-Trial Data'!$D17:$F17) | E32: =AVERAGE('Per-Trial Data'!$G17:$I17) | F32: =IF(COUNT('Per-Trial Data'!$G17:$I17)>1,STDEV('Per-Trial Data'!$G17:$I17)/SQRT(COUNT('Per-Trial Data'!$G17:$I17)),0) | G32: =AVERAGE('Per-Trial Data'!$J17:$L17) | H32: =IF(COUNT('Per-Trial Data'!$J17:$L17)>1,STDEV('Per-Trial Data'!$J17:$L17)/SQRT(COUNT('Per-Trial Data'!$J17:$L17)),0) | I32: =G32-E32 | J32: =SQRT(F32^2+H32^2) | K32: =AVERAGE('Per-Trial Data'!$M17:$O17) | L32: =IF(COUNT('Per-Trial Data'!$M17:$O17)>1,STDEV('Per-Trial Data'!$M17:$O17)/SQRT(COUNT('Per-Trial Data'!$M17:$O17)),0) | M32: =AVERAGE('Per-Trial Data'!$P17:$R17) | N32: =IF(COUNT('Per-Trial Data'!$P17:$R17)>1,STDEV('Per-Trial Data'!$P17:$R17)/SQRT(COUNT('Per-Trial Data'!$P17:$R17)),0) | O32: =M32-K32 | P32: =SQRT(L32^2+N32^2)
A33: 4G5J | B33: Afatinib | C33: EGFR | D33: =AVERAGE('Per-Trial Data'!$D28:$F28) | E33: =AVERAGE('Per-Trial Data'!$G28:$I28) | F33: =IF(COUNT('Per-Trial Data'!$G28:$I28)>1,STDEV('Per-Trial Data'!$G28:$I28)/SQRT(COUNT('Per-Trial Data'!$G28:$I28)),0) | G33: =AVERAGE('Per-Trial Data'!$J28:$L28) | H33: =IF(COUNT('Per-Trial Data'!$J28:$L28)>1,STDEV('Per-Trial Data'!$J28:$L28)/SQRT(COUNT('Per-Trial Data'!$J28:$L28)),0) | I33: =G33-E33 | J33: =SQRT(F33^2+H33^2) | K33: =AVERAGE('Per-Trial Data'!$M28:$O28) | L33: =IF(COUNT('Per-Trial Data'!$M28:$O28)>1,STDEV('Per-Trial Data'!$M28:$O28)/SQRT(COUNT('Per-Trial Data'!$M28:$O28)),0) | M33: =AVERAGE('Per-Trial Data'!$P28:$R28) | N33: =IF(COUNT('Per-Trial Data'!$P28:$R28)>1,STDEV('Per-Trial Data'!$P28:$R28)/SQRT(COUNT('Per-Trial Data'!$P28:$R28)),0) | O33: =M33-K33 | P33: =SQRT(L33^2+N33^2)
A34: 4G5P | B34: Afatinib | C34: EGFR | D34: =AVERAGE('Per-Trial Data'!$D29:$F29) | E34: =AVERAGE('Per-Trial Data'!$G29:$I29) | F34: =IF(COUNT('Per-Trial Data'!$G29:$I29)>1,STDEV('Per-Trial Data'!$G29:$I29)/SQRT(COUNT('Per-Trial Data'!$G29:$I29)),0) | G34: =AVERAGE('Per-Trial Data'!$J29:$L29) | H34: =IF(COUNT('Per-Trial Data'!$J29:$L29)>1,STDEV('Per-Trial Data'!$J29:$L29)/SQRT(COUNT('Per-Trial Data'!$J29:$L29)),0) | I34: =G34-E34 | J34: =SQRT(F34^2+H34^2) | K34: =AVERAGE('Per-Trial Data'!$M29:$O29) | L34: =IF(COUNT('Per-Trial Data'!$M29:$O29)>1,STDEV('Per-Trial Data'!$M29:$O29)/SQRT(COUNT('Per-Trial Data'!$M29:$O29)),0) | M34: =AVERAGE('Per-Trial Data'!$P29:$R29) | N34: =IF(COUNT('Per-Trial Data'!$P29:$R29)>1,STDEV('Per-Trial Data'!$P29:$R29)/SQRT(COUNT('Per-Trial Data'!$P29:$R29)),0) | O34: =M34-K34 | P34: =SQRT(L34^2+N34^2)
A35: 4I22 | B35: Gefitinib | C35: EGFR | D35: =AVERAGE('Per-Trial Data'!$D30:$F30) | E35: =AVERAGE('Per-Trial Data'!$G30:$I30) | F35: =IF(COUNT('Per-Trial Data'!$G30:$I30)>1,STDEV('Per-Trial Data'!$G30:$I30)/SQRT(COUNT('Per-Trial Data'!$G30:$I30)),0) | G35: =AVERAGE('Per-Trial Data'!$J30:$L30) | H35: =IF(COUNT('Per-Trial Data'!$J30:$L30)>1,STDEV('Per-Trial Data'!$J30:$L30)/SQRT(COUNT('Per-Trial Data'!$J30:$L30)),0) | I35: =G35-E35 | J35: =SQRT(F35^2+H35^2) | K35: =AVERAGE('Per-Trial Data'!$M30:$O30) | L35: =IF(COUNT('Per-Trial Data'!$M30:$O30)>1,STDEV('Per-Trial Data'!$M30:$O30)/SQRT(COUNT('Per-Trial Data'!$M30:$O30)),0) | M35: =AVERAGE('Per-Trial Data'!$P30:$R30) | N35: =IF(COUNT('Per-Trial Data'!$P30:$R30)>1,STDEV('Per-Trial Data'!$P30:$R30)/SQRT(COUNT('Per-Trial Data'!$P30:$R30)),0) | O35: =M35-K35 | P35: =SQRT(L35^2+N35^2)
A36: 4WKQ | B36: Gefitinib | C36: EGFR | D36: =AVERAGE('Per-Trial Data'!$D33:$F33) | E36: =AVERAGE('Per-Trial Data'!$G33:$I33) | F36: =IF(COUNT('Per-Trial Data'!$G33:$I33)>1,STDEV('Per-Trial Data'!$G33:$I33)/SQRT(COUNT('Per-Trial Data'!$G33:$I33)),0) | G36: =AVERAGE('Per-Trial Data'!$J33:$L33) | H36: =IF(COUNT('Per-Trial Data'!$J33:$L33)>1,STDEV('Per-Trial Data'!$J33:$L33)/SQRT(COUNT('Per-Trial Data'!$J33:$L33)),0) | I36: =G36-E36 | J36: =SQRT(F36^2+H36^2) | K36: =AVERAGE('Per-Trial Data'!$M33:$O33) | L36: =IF(COUNT('Per-Trial Data'!$M33:$O33)>1,STDEV('Per-Trial Data'!$M33:$O33)/SQRT(COUNT('Per-Trial Data'!$M33:$O33)),0) | M36: =AVERAGE('Per-Trial Data'!$P33:$R33) | N36: =IF(COUNT('Per-Trial Data'!$P33:$R33)>1,STDEV('Per-Trial Data'!$P33:$R33)/SQRT(COUNT('Per-Trial Data'!$P33:$R33)),0) | O36: =M36-K36 | P36: =SQRT(L36^2+N36^2)
A37: 4ZAU | B37: Osimertinib | C37: EGFR | D37: =AVERAGE('Per-Trial Data'!$D34:$F34) | E37: =AVERAGE('Per-Trial Data'!$G34:$I34) | F37: =IF(COUNT('Per-Trial Data'!$G34:$I34)>1,STDEV('Per-Trial Data'!$G34:$I34)/SQRT(COUNT('Per-Trial Data'!$G34:$I34)),0) | G37: =AVERAGE('Per-Trial Data'!$J34:$L34) | H37: =IF(COUNT('Per-Trial Data'!$J34:$L34)>1,STDEV('Per-Trial Data'!$J34:$L34)/SQRT(COUNT('Per-Trial Data'!$J34:$L34)),0) | I37: =G37-E37 | J37: =SQRT(F37^2+H37^2) | K37: =AVERAGE('Per-Trial Data'!$M34:$O34) | L37: =IF(COUNT('Per-Trial Data'!$M34:$O34)>1,STDEV('Per-Trial Data'!$M34:$O34)/SQRT(COUNT('Per-Trial Data'!$M34:$O34)),0) | M37: =AVERAGE('Per-Trial Data'!$P34:$R34) | N37: =IF(COUNT('Per-Trial Data'!$P34:$R34)>1,STDEV('Per-Trial Data'!$P34:$R34)/SQRT(COUNT('Per-Trial Data'!$P34:$R34)),0) | O37: =M37-K37 | P37: =SQRT(L37^2+N37^2)
B38: JAK3
A39: 3LXK | B39: Tofacitinib | C39: JAK3 | D39: =AVERAGE('Per-Trial Data'!$D14:$F14) | E39: =AVERAGE('Per-Trial Data'!$G14:$I14) | F39: =IF(COUNT('Per-Trial Data'!$G14:$I14)>1,STDEV('Per-Trial Data'!$G14:$I14)/SQRT(COUNT('Per-Trial Data'!$G14:$I14)),0) | G39: =AVERAGE('Per-Trial Data'!$J14:$L14) | H39: =IF(COUNT('Per-Trial Data'!$J14:$L14)>1,STDEV('Per-Trial Data'!$J14:$L14)/SQRT(COUNT('Per-Trial Data'!$J14:$L14)),0) | I39: =G39-E39 | J39: =SQRT(F39^2+H39^2) | K39: =AVERAGE('Per-Trial Data'!$M14:$O14) | L39: =IF(COUNT('Per-Trial Data'!$M14:$O14)>1,STDEV('Per-Trial Data'!$M14:$O14)/SQRT(COUNT('Per-Trial Data'!$M14:$O14)),0) | M39: =AVERAGE('Per-Trial Data'!$P14:$R14) | N39: =IF(COUNT('Per-Trial Data'!$P14:$R14)>1,STDEV('Per-Trial Data'!$P14:$R14)/SQRT(COUNT('Per-Trial Data'!$P14:$R14)),0) | O39: =M39-K39 | P39: =SQRT(L39^2+N39^2)
B40: MEK
A41: 4AN2 | B41: Cobimetinib | C41: MEK | D41: =AVERAGE('Per-Trial Data'!$D24:$F24) | E41: =AVERAGE('Per-Trial Data'!$G24:$I24) | F41: =IF(COUNT('Per-Trial Data'!$G24:$I24)>1,STDEV('Per-Trial Data'!$G24:$I24)/SQRT(COUNT('Per-Trial Data'!$G24:$I24)),0) | G41: =AVERAGE('Per-Trial Data'!$J24:$L24) | H41: =IF(COUNT('Per-Trial Data'!$J24:$L24)>1,STDEV('Per-Trial Data'!$J24:$L24)/SQRT(COUNT('Per-Trial Data'!$J24:$L24)),0) | I41: =G41-E41 | J41: =SQRT(F41^2+H41^2) | K41: =AVERAGE('Per-Trial Data'!$M24:$O24) | L41: =IF(COUNT('Per-Trial Data'!$M24:$O24)>1,STDEV('Per-Trial Data'!$M24:$O24)/SQRT(COUNT('Per-Trial Data'!$M24:$O24)),0) | M41: =AVERAGE('Per-Trial Data'!$P24:$R24) | N41: =IF(COUNT('Per-Trial Data'!$P24:$R24)>1,STDEV('Per-Trial Data'!$P24:$R24)/SQRT(COUNT('Per-Trial Data'!$P24:$R24)),0) | O41: =M41-K41 | P41: =SQRT(L41^2+N41^2)
...

Sheet Methods
A1: Methods: how the Trials statistics were computed
A2: Generated 2026-09-22 19:29:54 by make_trials_tables_xlsx.py
A4: Replicates
A5: n | B5: 3 independent trials of the full MCCE4 pipeline (steps 1-4)
A6: Trial01 | B6: MONTE_SEED = 1001
A7: Trial02 | B7: MONTE_SEED = 1002
A8: Trial03 | B8: MONTE_SEED = 1003
A9: What varies | B9: step2 rotamer generation does not reproduce between runs, so each trial has its own conformer set, and step4 Monte Carlo uses a per-trial seed. A trial is therefore the replicate unit: re-running step4 alone in a finished tree would hold the conformers fixed and understate the spread.
A11: Statistics
A12: mean | B12: arithmetic mean over the n trials
A13: SD | B13: sample standard deviation (n-1 denominator)
A14: SEM | B14: SD / √n — every ± column, and the plotted error bar
A15: ∆crg (Table 1) | B15: difference of the trial means; ± is the propagated SEM √(a²+b²)
A16: ∆q (per residue) | B16: holo − apo computed WITHIN each trial, then averaged. apo reuses holo's conformers inside a trial, so the pairing cancels the conformer set; combining two independent SEMs would overstate the error.
A18: Caveat | B18: Error bars are ±1 SEM, NOT a confidence interval. With n=3 there are 2 degrees of freedom, so a 95% CI would be mean ± 4.30 × SEM.
A19: Scope | B19: The spread reflects run-to-run reproducibility of the pipeline. It does not include force-field, dielectric (ε=4) or crystal-structure uncertainty.
A21: Provenance
A22: Charges | B22: xts_sum_crg.out at pH 7.4 — the entropy-corrected output of xts_corr.py, which step4 does not produce on its own
A23: Ligand #conf | B23: conformer count for the ligand in run_inhib/head3.lst
A24: Kinase | B24: the Kinase column of pdb_inhibitor.lst

Sheet Outliers (holo-apo)
A1: Tier | B1: PDB | C1: Inhibitor | D1: ResName | E1: Chain | F1: ResNum | G1: Residue | H1: ApoCharge | I1: HoloCharge | J1: DeltaCharge | K1: DeltaSEM | L1: DeltaMin | M1: DeltaMax | N1: Reproducible
A2: strong | B2: 4MKC | C2: Ceritinib | D2: LYS | E2: A | F2: 1205 | G2: LYS+A1205 | H2: 0.66 | I2: 0.15 | J2: -0.51 | K2: 0 | L2: -0.51 | M2: -0.51 | N2: yes
A3: affected | B3: 1XKK | C3: Lapatinib | D3: LYS | E3: A | F3: 745 | G3: LYS+A0745 | H3: 0.907 | I3: 0.55 | J3: -0.357 | K3: 0.007 | L3: -0.37 | M3: -0.35 | N3: yes
A4: affected | B4: 1XKK | C4: Lapatinib | D4: CYS | E4: A | F4: 775 | G4: CYS-A0775 | H4: -0.287 | I4: 0 | J4: 0.287 | K4: 0.009 | L4: 0.27 | M4: 0.3 | N4: yes
A5: affected | B5: 3UE4 | C5: Bosutinib | D5: GLU | E5: A | F5: 286 | G5: GLU-A0286 | H5: -0.307 | I5: -0.557 | J5: -0.25 | K5: 0.012 | L5: -0.27 | M5: -0.23 | N5: yes
A6: affected | B6: 4AN2 | C6: Cobimetinib | D6: CYS | E6: A | F6: 207 | G6: CYS-A0207 | H6: -0.733 | I6: -0.97 | J6: -0.237 | K6: 0.007 | L6: -0.25 | M6: -0.23 | N6: yes
A7: affected | B7: 4I22 | C7: Gefitinib | D7: HIS | E7: A | F7: 850 | G7: HIS+A0850 | H7: 0.78 | I7: 0.55 | J7: -0.23 | K7: 0.026 | L7: -0.28 | M7: -0.19 | N7: NO
A8: affected | B8: 2EUF | C8: Palbociclib | D8: LYS | E8: B | F8: 43 | G8: LYS+B0043 | H8: 0.9 | I8: 0.673 | J8: -0.227 | K8: 0.227 | L8: -0.68 | M8: 0 | N8: NO
A10: Reproducible = every trial clears the tier threshold. 'NO' means the classification depends on which trial you look at.

Sheet Reproducibility
A1: Is the mean a fair summary of the trials?
A3: Fig4A — per residue (holo vs apo)
A4: Category | B4: N | C4: Percent | D4: Meaning
A5: identical | B5: 3165 | C5: 86.3 | D5: all trials gave the same value; SEM is exactly 0
A6: scattered | B6: 502 | C6: 13.7 | D6: unimodal spread; mean +/- SEM is a fair summary
A7: two-state | B7: 1 | C7: 0 | D7: discrete bistability; the mean is a value never sampled
A9: # points NOT summarised well by mean +/- SEM
A10: Key | B10: PerTrial | C10: Range
A11: 2EUF/LYS+B0043_ | B11: -0.68;+0.00;+0.00 | C11: 0.68
A12: 4I22/HIS+A0850_ | B12: -0.28;-0.22;-0.19 | C12: 0.09
A13: 4I22/HIS+A0773_ | B13: +0.22;+0.18;+0.15 | C13: 0.07
A14: 2WGJ/HIS+A1094_ | B14: -0.13;-0.15;-0.19 | C14: 0.06
A16: Fig3 — per inhibitor (bound vs solution)
A17: Category | B17: N | C17: Percent | D17: Meaning
A18: identical | B18: 21 | C18: 56.8 | D18: all trials gave the same value; SEM is exactly 0
A19: scattered | B19: 15 | C19: 40.5 | D19: unimodal spread; mean +/- SEM is a fair summary
A20: two-state | B20: 1 | C20: 2.7 | D20: discrete bistability; the mean is a value never sampled
A22: # points NOT summarised well by mean +/- SEM
A23: Key | B23: PerTrial | C23: Range
A24: 3CS9 | B24: +0.17;+0.61;+0.19 | C24: 0.44
A25: 5MO4 | B25: +0.48;+0.21;+0.25 | C25: 0.27
A26: 3AOX | B26: +0.90;+0.79;+0.79 | C26: 0.11
A27: 2ITO | B27: +0.72;+0.77;+0.80 | C27: 0.08
A28: 4I22 | B28: +0.45;+0.47;+0.52 | C28: 0.07
A29: 4AN2 | B29: +0.23;+0.29;+0.22 | C29: 0.07
