Workbook

Sheet Per-Trial Data
D1: Ligand #conf | G1: Ligand crg soln | J1: Ligand crg bound | M1: Apo-kinase charge | P1: Holo-kinase charge
A2: PDBID | B2: Ligand | C2: Kinase | D2: T01 | E2: T02 | F2: T03 | G2: T01 | H2: T02 | I2: T03 | J2: T01 | K2: T02 | L2: T03 | M2: T01 | N2: T02 | O2: T03 | P2: T01 | Q2: T02 | R2: T03
A3: 1XKK | B3: Lapatinib | C3: EGFR | D3: 4 | E3: 5 | F3: 4 | G3: 0.95 | H3: 0.95 | I3: 0.95 | J3: 0.7 | K3: 0.5 | L3: 0.53 | M3: 0.47 | N3: 0.45 | O3: 0.51 | P3: 0.71 | Q3: 0.6 | R3: 0.67
A4: 2EUF | B4: Palbociclib | C4: CDK6 | D4: 2 | E4: 2 | F4: 2 | G4: 0.98 | H4: 0.98 | I4: 0.98 | J4: 1 | K4: 1 | L4: 1 | M4: -9.33 | N4: -9.68 | O4: -9.75 | P4: -8.5 | Q4: -8.86 | R4: -8.93
A5: 2HYY | B5: Imatinib | C5: ABL | D5: 5 | E5: 5 | F5: 5 | G5: 0.97 | H5: 0.97 | I5: 0.97 | J5: 1 | K5: 1 | L5: 1 | M5: -6.2 | N5: -6.18 | O5: -6.19 | P5: -5.4 | Q5: -5.34 | R5: -5.38
A6: 2ITO | B6: Gefitinib | C6: EGFR | D6: 5 | E6: 5 | F6: 5 | G6: 0.3 | H6: 0.3 | I6: 0.3 | J6: 0.75 | K6: 0.8 | L6: 0.8 | M6: -7 | N6: -7.13 | O6: -7.1 | P6: -6.4 | Q6: -6.51 | R6: -6.52
A7: 2ITY | B7: Gefitinib | C7: EGFR | D7: 5 | E7: 5 | F7: 5 | G7: 0.3 | H7: 0.3 | I7: 0.3 | J7: 0.35 | K7: 0.35 | L7: 0.35 | M7: -6.05 | N7: -6.01 | O7: -6.03 | P7: -5.77 | Q7: -5.74 | R7: -5.77
A8: 2ITZ | B8: Gefitinib | C8: EGFR | D8: 5 | E8: 5 | F8: 5 | G8: 0.3 | H8: 0.3 | I8: 0.3 | J8: 0.64 | K8: 0.65 | L8: 0.66 | M8: -4.69 | N8: -4.98 | O8: -4.95 | P8: -4.15 | Q8: -4.45 | R8: -4.38
A9: 2WGJ | B9: Crizotinib | C9: MET | D9: 5 | E9: 4 | F9: 4 | G9: 1.61 | H9: 1.61 | I9: 1.61 | J9: 0.96 | K9: 0.96 | L9: 0.97 | M9: 7 | N9: 7.02 | O9: 7.05 | P9: 7.71 | Q9: 7.74 | R9: 7.78
A10: 2XP2 | B10: Crizotinib | C10: ALK | D10: 4 | E10: 4 | F10: 4 | G10: 1.61 | H10: 1.61 | I10: 1.61 | J10: 1 | K10: 1 | L10: 1 | M10: -5.51 | N10: -5.96 | O10: -5.92 | P10: -4.58 | Q10: -5.01 | R10: -4.99
A11: 2YFX | B11: Crizotinib | C11: ALK | D11: 5 | E11: 4 | F11: 4 | G11: 1.61 | H11: 1.61 | I11: 1.61 | J11: 1 | K11: 1 | L11: 1 | M11: -4.59 | N11: -4.59 | O11: -4.59 | P11: -3.59 | Q11: -3.62 | R11: -3.61
A12: 3AOX | B12: Alectinib | C12: ALK | D12: 2 | E12: 2 | F12: 3 | G12: 0.56 | H12: 0.56 | I12: 0.56 | J12: 0.79 | K12: 0.9 | L12: 0.79 | M12: -8.4 | N12: -8.37 | O12: -8.36 | P12: -7.65 | Q12: -7.5 | R12: -7.63
A13: 3CS9 | B13: Nilotinib | C13: ABL | D13: 3 | E13: 3 | F13: 4 | G13: 0.09 | H13: 0.09 | I13: 0.09 | J13: 0.42 | K13: 0.63 | L13: 0.19 | M13: -4.62 | N13: -4.58 | O13: -4.61 | P13: -4.24 | Q13: -3.98 | R13: -4.42
A14: 3LXK | B14: Tofacitinib | C14: JAK3 | D14: 5 | E14: 5 | F14: 5 | G14: 0.03 | H14: 0.03 | I14: 0.03 | J14: 0.05 | K14: 0.04 | L14: 0.05 | M14: 1.14 | N14: 1.29 | O14: 1.1 | P14: 1.29 | Q14: 1.4 | R14: 1.22
... A39: 5MO4 | B39: Nilotinib | C39: ABL | D39: 3 | E39: 3 | F39: 3 | G39: 0.09 | H39: 0.09 | I39: 0.09 | J39: 0.23 | K39: 0.23 | L39: 0.25 | M39: -7.97 | N39: -7.89 | O39: -7.95 | P39: -7.77 | Q39: -7.66 | R39: -7.71
A41: Source: xts_sum_crg.out (pH 7.4, entropy-corrected by xts_corr.py) in each trial's run_inhib / run_holo / run_apo; #conf from run_inhib/head3.lst. These are the workbook's only hardcoded values.

Sheet Table 1 (Trials)
A1: Table 1 (Trials): inhibitor and kinase charge at pH 7.4, mean of 3 independent trials
A2: Each value is the mean over the trials; ± columns are the standard error of the mean (SD/√n). See the Methods sheet.
D4: Ligand | K4: Apo-kinase | M4: Holo-kinase | O4: Holo-Apo
A5: PDBID | B5: Ligand | C5: Kinase | D5: #conf | E5: crg soln | F5: ± SEM | G5: crg bound | H5: ± SEM | I5: ∆crg | J5: ± SEM | K5: charge | L5: ± SEM | M5: charge | N5: ± SEM | O5: ∆crg | P5: ± SEM
B6: ABL
A7: 3UE4 | B7: Bosutinib | C7: ABL | D7: =AVERAGE('Per-Trial Data'!$D16:$F16) | E7: =AVERAGE('Per-Trial Data'!$G16:$I16) | F7: =IF(COUNT('Per-Trial Data'!$G16:$I16)>1,STDEV('Per-Trial Data'!$G16:$I16)/SQRT(COUNT('Per-Trial Data'!$G16:$I16)),0) | G7: =AVERAGE('Per-Trial Data'!$J16:$L16) | H7: =IF(COUNT('Per-Trial Data'!$J16:$L16)>1,STDEV('Per-Trial Data'!$J16:$L16)/SQRT(COUNT('Per-Trial Data'!$J16:$L16)),0) | I7: =G7-E7 | J7: =SQRT(F7^2+H7^2) | K7: =AVERAGE('Per-Trial Data'!$M16:$O16) | L7: =IF(COUNT('Per-Trial Data'!$M16:$O16)>1,STDEV('Per-Trial Data'!$M16:$O16)/SQRT(COUNT('Per-Trial Data'!$M16:$O16)),0) | M7: =AVERAGE('Per-Trial Data'!$P16:$R16) | N7: =IF(COUNT('Per-Trial Data'!$P16:$R16)>1,STDEV('Per-Trial Data'!$P16:$R16)/SQRT(COUNT('Per-Trial Data'!$P16:$R16)),0) | O7: =M7-K7 | P7: =SQRT(L7^2+N7^2)
A8: 2HYY | B8: Imatinib | C8: ABL | D8: =AVERAGE('Per-Trial Data'!$D5:$F5) | E8: =AVERAGE('Per-Trial Data'!$G5:$I5) | F8: =IF(COUNT('Per-Trial Data'!$G5:$I5)>1,STDEV('Per-Trial Data'!$G5:$I5)/SQRT(COUNT('Per-Trial Data'!$G5:$I5)),0) | G8: =AVERAGE('Per-Trial Data'!$J5:$L5) | H8: =IF(COUNT('Per-Trial Data'!$J5:$L5)>1,STDEV('Per-Trial Data'!$J5:$L5)/SQRT(COUNT('Per-Trial Data'!$J5:$L5)),0) | I8: =G8-E8 | J8: =SQRT(F8^2+H8^2) | K8: =AVERAGE('Per-Trial Data'!$M5:$O5) | L8: =IF(COUNT('Per-Trial Data'!$M5:$O5)>1,STDEV('Per-Trial Data'!$M5:$O5)/SQRT(COUNT('Per-Trial Data'!$M5:$O5)),0) | M8: =AVERAGE('Per-Trial Data'!$P5:$R5) | N8: =IF(COUNT('Per-Trial Data'!$P5:$R5)>1,STDEV('Per-Trial Data'!$P5:$R5)/SQRT(COUNT('Per-Trial Data'!$P5:$R5)),0) | O8: =M8-K8 | P8: =SQRT(L8^2+N8^2)
A9: 3PYY | B9: Imatinib | C9: ABL | D9: =AVERAGE('Per-Trial Data'!$D15:$F15) | E9: =AVERAGE('Per-Trial Data'!$G15:$I15) | F9: =IF(COUNT('Per-Trial Data'!$G15:$I15)>1,STDEV('Per-Trial Data'!$G15:$I15)/SQRT(COUNT('Per-Trial Data'!$G15:$I15)),0) | G9: =AVERAGE('Per-Trial Data'!$J15:$L15) | H9: =IF(COUNT('Per-Trial Data'!$J15:$L15)>1,STDEV('Per-Trial Data'!$J15:$L15)/SQRT(COUNT('Per-Trial Data'!$J15:$L15)),0) | I9: =G9-E9 | J9: =SQRT(F9^2+H9^2) | K9: =AVERAGE('Per-Trial Data'!$M15:$O15) | L9: =IF(COUNT('Per-Trial Data'!$M15:$O15)>1,STDEV('Per-Trial Data'!$M15:$O15)/SQRT(COUNT('Per-Trial Data'!$M15:$O15)),0) | M9: =AVERAGE('Per-Trial Data'!$P15:$R15) | N9: =IF(COUNT('Per-Trial Data'!$P15:$R15)>1,STDEV('Per-Trial Data'!$P15:$R15)/SQRT(COUNT('Per-Trial Data'!$P15:$R15)),0) | O9: =M9-K9 | P9: =SQRT(L9^2+N9^2)
A10: 3CS9 | B10: Nilotinib | C10: ABL | D10: =AVERAGE('Per-Trial Data'!$D13:$F13) | E10: =AVERAGE('Per-Trial Data'!$G13:$I13) | F10: =IF(COUNT('Per-Trial Data'!$G13:$I13)>1,STDEV('Per-Trial Data'!$G13:$I13)/SQRT(COUNT('Per-Trial Data'!$G13:$I13)),0) | G10: =AVERAGE('Per-Trial Data'!$J13:$L13) | H10: =IF(COUNT('Per-Trial Data'!$J13:$L13)>1,STDEV('Per-Trial Data'!$J13:$L13)/SQRT(COUNT('Per-Trial Data'!$J13:$L13)),0) | I10: =G10-E10 | J10: =SQRT(F10^2+H10^2) | K10: =AVERAGE('Per-Trial Data'!$M13:$O13) | L10: =IF(COUNT('Per-Trial Data'!$M13:$O13)>1,STDEV('Per-Trial Data'!$M13:$O13)/SQRT(COUNT('Per-Trial Data'!$M13:$O13)),0) | M10: =AVERAGE('Per-Trial Data'!$P13:$R13) | N10: =IF(COUNT('Per-Trial Data'!$P13:$R13)>1,STDEV('Per-Trial Data'!$P13:$R13)/SQRT(COUNT('Per-Trial Data'!$P13:$R13)),0) | O10: =M10-K10 | P10: =SQRT(L10^2+N10^2)
A11: 5MO4 | B11: Nilotinib | C11: ABL | D11: =AVERAGE('Per-Trial Data'!$D39:$F39) | E11: =AVERAGE('Per-Trial Data'!$G39:$I39) | F11: =IF(COUNT('Per-Trial Data'!$G39:$I39)>1,STDEV('Per-Trial Data'!$G39:$I39)/SQRT(COUNT('Per-Trial Data'!$G39:$I39)),0) | G11: =AVERAGE('Per-Trial Data'!$J39:$L39) | H11: =IF(COUNT('Per-Trial Data'!$J39:$L39)>1,STDEV('Per-Trial Data'!$J39:$L39)/SQRT(COUNT('Per-Trial Data'!$J39:$L39)),0) | I11: =G11-E11 | J11: =SQRT(F11^2+H11^2) | K11: =AVERAGE('Per-Trial Data'!$M39:$O39) | L11: =IF(COUNT('Per-Trial Data'!$M39:$O39)>1,STDEV('Per-Trial Data'!$M39:$O39)/SQRT(COUNT('Per-Trial Data'!$M39:$O39)),0) | M11: =AVERAGE('Per-Trial Data'!$P39:$R39) | N11: =IF(COUNT('Per-Trial Data'!$P39:$R39)>1,STDEV('Per-Trial Data'!$P39:$R39)/SQRT(COUNT('Per-Trial Data'!$P39:$R39)),0) | O11: =M11-K11 | P11: =SQRT(L11^2+N11^2)
B12: ALK
A13: 3AOX | B13: Alectinib | C13: ALK | D13: =AVERAGE('Per-Trial Data'!$D12:$F12) | E13: =AVERAGE('Per-Trial Data'!$G12:$I12) | F13: =IF(COUNT('Per-Trial Data'!$G12:$I12)>1,STDEV('Per-Trial Data'!$G12:$I12)/SQRT(COUNT('Per-Trial Data'!$G12:$I12)),0) | G13: =AVERAGE('Per-Trial Data'!$J12:$L12) | H13: =IF(COUNT('Per-Trial Data'!$J12:$L12)>1,STDEV('Per-Trial Data'!$J12:$L12)/SQRT(COUNT('Per-Trial Data'!$J12:$L12)),0) | I13: =G13-E13 | J13: =SQRT(F13^2+H13^2) | K13: =AVERAGE('Per-Trial Data'!$M12:$O12) | L13: =IF(COUNT('Per-Trial Data'!$M12:$O12)>1,STDEV('Per-Trial Data'!$M12:$O12)/SQRT(COUNT('Per-Trial Data'!$M12:$O12)),0) | M13: =AVERAGE('Per-Trial Data'!$P12:$R12) | N13: =IF(COUNT('Per-Trial Data'!$P12:$R12)>1,STDEV('Per-Trial Data'!$P12:$R12)/SQRT(COUNT('Per-Trial Data'!$P12:$R12)),0) | O13: =M13-K13 | P13: =SQRT(L13^2+N13^2)
A14: 4MKC | B14: Ceritinib | C14: ALK | D14: =AVERAGE('Per-Trial Data'!$D32:$F32) | E14: =AVERAGE('Per-Trial Data'!$G32:$I32) | F14: =IF(COUNT('Per-Trial Data'!$G32:$I32)>1,STDEV('Per-Trial Data'!$G32:$I32)/SQRT(COUNT('Per-Trial Data'!$G32:$I32)),0) | G14: =AVERAGE('Per-Trial Data'!$J32:$L32) | H14: =IF(COUNT('Per-Trial Data'!$J32:$L32)>1,STDEV('Per-Trial Data'!$J32:$L32)/SQRT(COUNT('Per-Trial Data'!$J32:$L32)),0) | I14: =G14-E14 | J14: =SQRT(F14^2+H14^2) | K14: =AVERAGE('Per-Trial Data'!$M32:$O32) | L14: =IF(COUNT('Per-Trial Data'!$M32:$O32)>1,STDEV('Per-Trial Data'!$M32:$O32)/SQRT(COUNT('Per-Trial Data'!$M32:$O32)),0) | M14: =AVERAGE('Per-Trial Data'!$P32:$R32) | N14: =IF(COUNT('Per-Trial Data'!$P32:$R32)>1,STDEV('Per-Trial Data'!$P32:$R32)/SQRT(COUNT('Per-Trial Data'!$P32:$R32)),0) | O14: =M14-K14 | P14: =SQRT(L14^2+N14^2)
A15: 2XP2 | B15: Crizotinib | C15: ALK | D15: =AVERAGE('Per-Trial Data'!$D10:$F10) | E15: =AVERAGE('Per-Trial Data'!$G10:$I10) | F15: =IF(COUNT('Per-Trial Data'!$G10:$I10)>1,STDEV('Per-Trial Data'!$G10:$I10)/SQRT(COUNT('Per-Trial Data'!$G10:$I10)),0) | G15: =AVERAGE('Per-Trial Data'!$J10:$L10) | H15: =IF(COUNT('Per-Trial Data'!$J10:$L10)>1,STDEV('Per-Trial Data'!$J10:$L10)/SQRT(COUNT('Per-Trial Data'!$J10:$L10)),0) | I15: =G15-E15 | J15: =SQRT(F15^2+H15^2) | K15: =AVERAGE('Per-Trial Data'!$M10:$O10) | L15: =IF(COUNT('Per-Trial Data'!$M10:$O10)>1,STDEV('Per-Trial Data'!$M10:$O10)/SQRT(COUNT('Per-Trial Data'!$M10:$O10)),0) | M15: =AVERAGE('Per-Trial Data'!$P10:$R10) | N15: =IF(COUNT('Per-Trial Data'!$P10:$R10)>1,STDEV('Per-Trial Data'!$P10:$R10)/SQRT(COUNT('Per-Trial Data'!$P10:$R10)),0) | O15: =M15-K15 | P15: =SQRT(L15^2+N15^2)
A16: 2YFX | B16: Crizotinib | C16: ALK | D16: =AVERAGE('Per-Trial Data'!$D11:$F11) | E16: =AVERAGE('Per-Trial Data'!$G11:$I11) | F16: =IF(COUNT('Per-Trial Data'!$G11:$I11)>1,STDEV('Per-Trial Data'!$G11:$I11)/SQRT(COUNT('Per-Trial Data'!$G11:$I11)),0) | G16: =AVERAGE('Per-Trial Data'!$J11:$L11) | H16: =IF(COUNT('Per-Trial Data'!$J11:$L11)>1,STDEV('Per-Trial Data'!$J11:$L11)/SQRT(COUNT('Per-Trial Data'!$J11:$L11)),0) | I16: =G16-E16 | J16: =SQRT(F16^2+H16^2) | K16: =AVERAGE('Per-Trial Data'!$M11:$O11) | L16: =IF(COUNT('Per-Trial Data'!$M11:$O11)>1,STDEV('Per-Trial Data'!$M11:$O11)/SQRT(COUNT('Per-Trial Data'!$M11:$O11)),0) | M16: =AVERAGE('Per-Trial Data'!$P11:$R11) | N16: =IF(COUNT('Per-Trial Data'!$P11:$R11)>1,STDEV('Per-Trial Data'!$P11:$R11)/SQRT(COUNT('Per-Trial Data'!$P11:$R11)),0) | O16: =M16-K16 | P16: =SQRT(L16^2+N16^2)
A17: 4ANQ | B17: Crizotinib | C17: ALK | D17: =AVERAGE('Per-Trial Data'!$D25:$F25) | E17: =AVERAGE('Per-Trial Data'!$G25:$I25) | F17: =IF(COUNT('Per-Trial Data'!$G25:$I25)>1,STDEV('Per-Trial Data'!$G25:$I25)/SQRT(COUNT('Per-Trial Data'!$G25:$I25)),0) | G17: =AVERAGE('Per-Trial Data'!$J25:$L25) | H17: =IF(COUNT('Per-Trial Data'!$J25:$L25)>1,STDEV('Per-Trial Data'!$J25:$L25)/SQRT(COUNT('Per-Trial Data'!$J25:$L25)),0) | I17: =G17-E17 | J17: =SQRT(F17^2+H17^2) | K17: =AVERAGE('Per-Trial Data'!$M25:$O25) | L17: =IF(COUNT('Per-Trial Data'!$M25:$O25)>1,STDEV('Per-Trial Data'!$M25:$O25)/SQRT(COUNT('Per-Trial Data'!$M25:$O25)),0) | M17: =AVERAGE('Per-Trial Data'!$P25:$R25) | N17: =IF(COUNT('Per-Trial Data'!$P25:$R25)>1,STDEV('Per-Trial Data'!$P25:$R25)/SQRT(COUNT('Per-Trial Data'!$P25:$R25)),0) | O17: =M17-K17 | P17: =SQRT(L17^2+N17^2)
A18: 4ANS | B18: Crizotinib | C18: ALK | D18: =AVERAGE('Per-Trial Data'!$D26:$F26) | E18: =AVERAGE('Per-Trial Data'!$G26:$I26) | F18: =IF(COUNT('Per-Trial Data'!$G26:$I26)>1,STDEV('Per-Trial Data'!$G26:$I26)/SQRT(COUNT('Per-Trial Data'!$G26:$I26)),0) | G18: =AVERAGE('Per-Trial Data'!$J26:$L26) | H18: =IF(COUNT('Per-Trial Data'!$J26:$L26)>1,STDEV('Per-Trial Data'!$J26:$L26)/SQRT(COUNT('Per-Trial Data'!$J26:$L26)),0) | I18: =G18-E18 | J18: =SQRT(F18^2+H18^2) | K18: =AVERAGE('Per-Trial Data'!$M26:$O26) | L18: =IF(COUNT('Per-Trial Data'!$M26:$O26)>1,STDEV('Per-Trial Data'!$M26:$O26)/SQRT(COUNT('Per-Trial Data'!$M26:$O26)),0) | M18: =AVERAGE('Per-Trial Data'!$P26:$R26) | N18: =IF(COUNT('Per-Trial Data'!$P26:$R26)>1,STDEV('Per-Trial Data'!$P26:$R26)/SQRT(COUNT('Per-Trial Data'!$P26:$R26)),0) | O18: =M18-K18 | P18: =SQRT(L18^2+N18^2)
A19: 5AAA | B19: Crizotinib | C19: ALK | D19: =AVERAGE('Per-Trial Data'!$D35:$F35) | E19: =AVERAGE('Per-Trial Data'!$G35:$I35) | F19: =IF(COUNT('Per-Trial Data'!$G35:$I35)>1,STDEV('Per-Trial Data'!$G35:$I35)/SQRT(COUNT('Per-Trial Data'!$G35:$I35)),0) | G19: =AVERAGE('Per-Trial Data'!$J35:$L35) | H19: =IF(COUNT('Per-Trial Data'!$J35:$L35)>1,STDEV('Per-Trial Data'!$J35:$L35)/SQRT(COUNT('Per-Trial Data'!$J35:$L35)),0) | I19: =G19-E19 | J19: =SQRT(F19^2+H19^2) | K19: =AVERAGE('Per-Trial Data'!$M35:$O35) | L19: =IF(COUNT('Per-Trial Data'!$M35:$O35)>1,STDEV('Per-Trial Data'!$M35:$O35)/SQRT(COUNT('Per-Trial Data'!$M35:$O35)),0) | M19: =AVERAGE('Per-Trial Data'!$P35:$R35) | N19: =IF(COUNT('Per-Trial Data'!$P35:$R35)>1,STDEV('Per-Trial Data'!$P35:$R35)/SQRT(COUNT('Per-Trial Data'!$P35:$R35)),0) | O19: =M19-K19 | P19: =SQRT(L19^2+N19^2)
A20: 5AAB | B20: Crizotinib | C20: ALK | D20: =AVERAGE('Per-Trial Data'!$D36:$F36) | E20: =AVERAGE('Per-Trial Data'!$G36:$I36) | F20: =IF(COUNT('Per-Trial Data'!$G36:$I36)>1,STDEV('Per-Trial Data'!$G36:$I36)/SQRT(COUNT('Per-Trial Data'!$G36:$I36)),0) | G20: =AVERAGE('Per-Trial Data'!$J36:$L36) | H20: =IF(COUNT('Per-Trial Data'!$J36:$L36)>1,STDEV('Per-Trial Data'!$J36:$L36)/SQRT(COUNT('Per-Trial Data'!$J36:$L36)),0) | I20: =G20-E20 | J20: =SQRT(F20^2+H20^2) | K20: =AVERAGE('Per-Trial Data'!$M36:$O36) | L20: =IF(COUNT('Per-Trial Data'!$M36:$O36)>1,STDEV('Per-Trial Data'!$M36:$O36)/SQRT(COUNT('Per-Trial Data'!$M36:$O36)),0) | M20: =AVERAGE('Per-Trial Data'!$P36:$R36) | N20: =IF(COUNT('Per-Trial Data'!$P36:$R36)>1,STDEV('Per-Trial Data'!$P36:$R36)/SQRT(COUNT('Per-Trial Data'!$P36:$R36)),0) | O20: =M20-K20 | P20: =SQRT(L20^2+N20^2)
A21: 5AAC | B21: Crizotinib | C21: ALK | D21: =AVERAGE('Per-Trial Data'!$D37:$F37) | E21: =AVERAGE('Per-Trial Data'!$G37:$I37) | F21: =IF(COUNT('Per-Trial Data'!$G37:$I37)>1,STDEV('Per-Trial Data'!$G37:$I37)/SQRT(COUNT('Per-Trial Data'!$G37:$I37)),0) | G21: =AVERAGE('Per-Trial Data'!$J37:$L37) | H21: =IF(COUNT('Per-Trial Data'!$J37:$L37)>1,STDEV('Per-Trial Data'!$J37:$L37)/SQRT(COUNT('Per-Trial Data'!$J37:$L37)),0) | I21: =G21-E21 | J21: =SQRT(F21^2+H21^2) | K21: =AVERAGE('Per-Trial Data'!$M37:$O37) | L21: =IF(COUNT('Per-Trial Data'!$M37:$O37)>1,STDEV('Per-Trial Data'!$M37:$O37)/SQRT(COUNT('Per-Trial Data'!$M37:$O37)),0) | M21: =AVERAGE('Per-Trial Data'!$P37:$R37) | N21: =IF(COUNT('Per-Trial Data'!$P37:$R37)>1,STDEV('Per-Trial Data'!$P37:$R37)/SQRT(COUNT('Per-Trial Data'!$P37:$R37)),0) | O21: =M21-K21 | P21: =SQRT(L21^2+N21^2)
B22: CDK6
A23: 2EUF | B23: Palbociclib | C23: CDK6 | D23: =AVERAGE('Per-Trial Data'!$D4:$F4) | E23: =AVERAGE('Per-Trial Data'!$G4:$I4) | F23: =IF(COUNT('Per-Trial Data'!$G4:$I4)>1,STDEV('Per-Trial Data'!$G4:$I4)/SQRT(COUNT('Per-Trial Data'!$G4:$I4)),0) | G23: =AVERAGE('Per-Trial Data'!$J4:$L4) | H23: =IF(COUNT('Per-Trial Data'!$J4:$L4)>1,STDEV('Per-Trial Data'!$J4:$L4)/SQRT(COUNT('Per-Trial Data'!$J4:$L4)),0) | I23: =G23-E23 | J23: =SQRT(F23^2+H23^2) | K23: =AVERAGE('Per-Trial Data'!$M4:$O4) | L23: =IF(COUNT('Per-Trial Data'!$M4:$O4)>1,STDEV('Per-Trial Data'!$M4:$O4)/SQRT(COUNT('Per-Trial Data'!$M4:$O4)),0) | M23: =AVERAGE('Per-Trial Data'!$P4:$R4) | N23: =IF(COUNT('Per-Trial Data'!$P4:$R4)>1,STDEV('Per-Trial Data'!$P4:$R4)/SQRT(COUNT('Per-Trial Data'!$P4:$R4)),0) | O23: =M23-K23 | P23: =SQRT(L23^2+N23^2)
A24: 5L2I | B24: Palbociclib | C24: CDK6 | D24: =AVERAGE('Per-Trial Data'!$D38:$F38) | E24: =AVERAGE('Per-Trial Data'!$G38:$I38) | F24: =IF(COUNT('Per-Trial Data'!$G38:$I38)>1,STDEV('Per-Trial Data'!$G38:$I38)/SQRT(COUNT('Per-Trial Data'!$G38:$I38)),0) | G24: =AVERAGE('Per-Trial Data'!$J38:$L38) | H24: =IF(COUNT('Per-Trial Data'!$J38:$L38)>1,STDEV('Per-Trial Data'!$J38:$L38)/SQRT(COUNT('Per-Trial Data'!$J38:$L38)),0) | I24: =G24-E24 | J24: =SQRT(F24^2+H24^2) | K24: =AVERAGE('Per-Trial Data'!$M38:$O38) | L24: =IF(COUNT('Per-Trial Data'!$M38:$O38)>1,STDEV('Per-Trial Data'!$M38:$O38)/SQRT(COUNT('Per-Trial Data'!$M38:$O38)),0) | M24: =AVERAGE('Per-Trial Data'!$P38:$R38) | N24: =IF(COUNT('Per-Trial Data'!$P38:$R38)>1,STDEV('Per-Trial Data'!$P38:$R38)/SQRT(COUNT('Per-Trial Data'!$P38:$R38)),0) | O24: =M24-K24 | P24: =SQRT(L24^2+N24^2)
B25: DDR1
A26: 3ZOS | B26: Ponatinib | C26: DDR1 | D26: =AVERAGE('Per-Trial Data'!$D20:$F20) | E26: =AVERAGE('Per-Trial Data'!$G20:$I20) | F26: =IF(COUNT('Per-Trial Data'!$G20:$I20)>1,STDEV('Per-Trial Data'!$G20:$I20)/SQRT(COUNT('Per-Trial Data'!$G20:$I20)),0) | G26: =AVERAGE('Per-Trial Data'!$J20:$L20) | H26: =IF(COUNT('Per-Trial Data'!$J20:$L20)>1,STDEV('Per-Trial Data'!$J20:$L20)/SQRT(COUNT('Per-Trial Data'!$J20:$L20)),0) | I26: =G26-E26 | J26: =SQRT(F26^2+H26^2) | K26: =AVERAGE('Per-Trial Data'!$M20:$O20) | L26: =IF(COUNT('Per-Trial Data'!$M20:$O20)>1,STDEV('Per-Trial Data'!$M20:$O20)/SQRT(COUNT('Per-Trial Data'!$M20:$O20)),0) | M26: =AVERAGE('Per-Trial Data'!$P20:$R20) | N26: =IF(COUNT('Per-Trial Data'!$P20:$R20)>1,STDEV('Per-Trial Data'!$P20:$R20)/SQRT(COUNT('Per-Trial Data'!$P20:$R20)),0) | O26: =M26-K26 | P26: =SQRT(L26^2+N26^2)
B27: EGFR
A28: 4G5J | B28: Afatinib | C28: EGFR | D28: =AVERAGE('Per-Trial Data'!$D28:$F28) | E28: =AVERAGE('Per-Trial Data'!$G28:$I28) | F28: =IF(COUNT('Per-Trial Data'!$G28:$I28)>1,STDEV('Per-Trial Data'!$G28:$I28)/SQRT(COUNT('Per-Trial Data'!$G28:$I28)),0) | G28: =AVERAGE('Per-Trial Data'!$J28:$L28) | H28: =IF(COUNT('Per-Trial Data'!$J28:$L28)>1,STDEV('Per-Trial Data'!$J28:$L28)/SQRT(COUNT('Per-Trial Data'!$J28:$L28)),0) | I28: =G28-E28 | J28: =SQRT(F28^2+H28^2) | K28: =AVERAGE('Per-Trial Data'!$M28:$O28) | L28: =IF(COUNT('Per-Trial Data'!$M28:$O28)>1,STDEV('Per-Trial Data'!$M28:$O28)/SQRT(COUNT('Per-Trial Data'!$M28:$O28)),0) | M28: =AVERAGE('Per-Trial Data'!$P28:$R28) | N28: =IF(COUNT('Per-Trial Data'!$P28:$R28)>1,STDEV('Per-Trial Data'!$P28:$R28)/SQRT(COUNT('Per-Trial Data'!$P28:$R28)),0) | O28: =M28-K28 | P28: =SQRT(L28^2+N28^2)
A29: 4G5P | B29: Afatinib | C29: EGFR | D29: =AVERAGE('Per-Trial Data'!$D29:$F29) | E29: =AVERAGE('Per-Trial Data'!$G29:$I29) | F29: =IF(COUNT('Per-Trial Data'!$G29:$I29)>1,STDEV('Per-Trial Data'!$G29:$I29)/SQRT(COUNT('Per-Trial Data'!$G29:$I29)),0) | G29: =AVERAGE('Per-Trial Data'!$J29:$L29) | H29: =IF(COUNT('Per-Trial Data'!$J29:$L29)>1,STDEV('Per-Trial Data'!$J29:$L29)/SQRT(COUNT('Per-Trial Data'!$J29:$L29)),0) | I29: =G29-E29 | J29: =SQRT(F29^2+H29^2) | K29: =AVERAGE('Per-Trial Data'!$M29:$O29) | L29: =IF(COUNT('Per-Trial Data'!$M29:$O29)>1,STDEV('Per-Trial Data'!$M29:$O29)/SQRT(COUNT('Per-Trial Data'!$M29:$O29)),0) | M29: =AVERAGE('Per-Trial Data'!$P29:$R29) | N29: =IF(COUNT('Per-Trial Data'!$P29:$R29)>1,STDEV('Per-Trial Data'!$P29:$R29)/SQRT(COUNT('Per-Trial Data'!$P29:$R29)),0) | O29: =M29-K29 | P29: =SQRT(L29^2+N29^2)
A30: 2ITO | B30: Gefitinib | C30: EGFR | D30: =AVERAGE('Per-Trial Data'!$D6:$F6) | E30: =AVERAGE('Per-Trial Data'!$G6:$I6) | F30: =IF(COUNT('Per-Trial Data'!$G6:$I6)>1,STDEV('Per-Trial Data'!$G6:$I6)/SQRT(COUNT('Per-Trial Data'!$G6:$I6)),0) | G30: =AVERAGE('Per-Trial Data'!$J6:$L6) | H30: =IF(COUNT('Per-Trial Data'!$J6:$L6)>1,STDEV('Per-Trial Data'!$J6:$L6)/SQRT(COUNT('Per-Trial Data'!$J6:$L6)),0) | I30: =G30-E30 | J30: =SQRT(F30^2+H30^2) | K30: =AVERAGE('Per-Trial Data'!$M6:$O6) | L30: =IF(COUNT('Per-Trial Data'!$M6:$O6)>1,STDEV('Per-Trial Data'!$M6:$O6)/SQRT(COUNT('Per-Trial Data'!$M6:$O6)),0) | M30: =AVERAGE('Per-Trial Data'!$P6:$R6) | N30: =IF(COUNT('Per-Trial Data'!$P6:$R6)>1,STDEV('Per-Trial Data'!$P6:$R6)/SQRT(COUNT('Per-Trial Data'!$P6:$R6)),0) | O30: =M30-K30 | P30: =SQRT(L30^2+N30^2)
A31: 2ITY | B31: Gefitinib | C31: EGFR | D31: =AVERAGE('Per-Trial Data'!$D7:$F7) | E31: =AVERAGE('Per-Trial Data'!$G7:$I7) | F31: =IF(COUNT('Per-Trial Data'!$G7:$I7)>1,STDEV('Per-Trial Data'!$G7:$I7)/SQRT(COUNT('Per-Trial Data'!$G7:$I7)),0) | G31: =AVERAGE('Per-Trial Data'!$J7:$L7) | H31: =IF(COUNT('Per-Trial Data'!$J7:$L7)>1,STDEV('Per-Trial Data'!$J7:$L7)/SQRT(COUNT('Per-Trial Data'!$J7:$L7)),0) | I31: =G31-E31 | J31: =SQRT(F31^2+H31^2) | K31: =AVERAGE('Per-Trial Data'!$M7:$O7) | L31: =IF(COUNT('Per-Trial Data'!$M7:$O7)>1,STDEV('Per-Trial Data'!$M7:$O7)/SQRT(COUNT('Per-Trial Data'!$M7:$O7)),0) | M31: =AVERAGE('Per-Trial Data'!$P7:$R7) | N31: =IF(COUNT('Per-Trial Data'!$P7:$R7)>1,STDEV('Per-Trial Data'!$P7:$R7)/SQRT(COUNT('Per-Trial Data'!$P7:$R7)),0) | O31: =M31-K31 | P31: =SQRT(L31^2+N31^2)
A32: 2ITZ | B32: Gefitinib | C32: EGFR | D32: =AVERAGE('Per-Trial Data'!$D8:$F8) | E32: =AVERAGE('Per-Trial Data'!$G8:$I8) | F32: =IF(COUNT('Per-Trial Data'!$G8:$I8)>1,STDEV('Per-Trial Data'!$G8:$I8)/SQRT(COUNT('Per-Trial Data'!$G8:$I8)),0) | G32: =AVERAGE('Per-Trial Data'!$J8:$L8) | H32: =IF(COUNT('Per-Trial Data'!$J8:$L8)>1,STDEV('Per-Trial Data'!$J8:$L8)/SQRT(COUNT('Per-Trial Data'!$J8:$L8)),0) | I32: =G32-E32 | J32: =SQRT(F32^2+H32^2) | K32: =AVERAGE('Per-Trial Data'!$M8:$O8) | L32: =IF(COUNT('Per-Trial Data'!$M8:$O8)>1,STDEV('Per-Trial Data'!$M8:$O8)/SQRT(COUNT('Per-Trial Data'!$M8:$O8)),0) | M32: =AVERAGE('Per-Trial Data'!$P8:$R8) | N32: =IF(COUNT('Per-Trial Data'!$P8:$R8)>1,STDEV('Per-Trial Data'!$P8:$R8)/SQRT(COUNT('Per-Trial Data'!$P8:$R8)),0) | O32: =M32-K32 | P32: =SQRT(L32^2+N32^2)
A33: 3UG2 | B33: Gefitinib | C33: EGFR | D33: =AVERAGE('Per-Trial Data'!$D17:$F17) | E33: =AVERAGE('Per-Trial Data'!$G17:$I17) | F33: =IF(COUNT('Per-Trial Data'!$G17:$I17)>1,STDEV('Per-Trial Data'!$G17:$I17)/SQRT(COUNT('Per-Trial Data'!$G17:$I17)),0) | G33: =AVERAGE('Per-Trial Data'!$J17:$L17) | H33: =IF(COUNT('Per-Trial Data'!$J17:$L17)>1,STDEV('Per-Trial Data'!$J17:$L17)/SQRT(COUNT('Per-Trial Data'!$J17:$L17)),0) | I33: =G33-E33 | J33: =SQRT(F33^2+H33^2) | K33: =AVERAGE('Per-Trial Data'!$M17:$O17) | L33: =IF(COUNT('Per-Trial Data'!$M17:$O17)>1,STDEV('Per-Trial Data'!$M17:$O17)/SQRT(COUNT('Per-Trial Data'!$M17:$O17)),0) | M33: =AVERAGE('Per-Trial Data'!$P17:$R17) | N33: =IF(COUNT('Per-Trial Data'!$P17:$R17)>1,STDEV('Per-Trial Data'!$P17:$R17)/SQRT(COUNT('Per-Trial Data'!$P17:$R17)),0) | O33: =M33-K33 | P33: =SQRT(L33^2+N33^2)
A34: 4I22 | B34: Gefitinib | C34: EGFR | D34: =AVERAGE('Per-Trial Data'!$D30:$F30) | E34: =AVERAGE('Per-Trial Data'!$G30:$I30) | F34: =IF(COUNT('Per-Trial Data'!$G30:$I30)>1,STDEV('Per-Trial Data'!$G30:$I30)/SQRT(COUNT('Per-Trial Data'!$G30:$I30)),0) | G34: =AVERAGE('Per-Trial Data'!$J30:$L30) | H34: =IF(COUNT('Per-Trial Data'!$J30:$L30)>1,STDEV('Per-Trial Data'!$J30:$L30)/SQRT(COUNT('Per-Trial Data'!$J30:$L30)),0) | I34: =G34-E34 | J34: =SQRT(F34^2+H34^2) | K34: =AVERAGE('Per-Trial Data'!$M30:$O30) | L34: =IF(COUNT('Per-Trial Data'!$M30:$O30)>1,STDEV('Per-Trial Data'!$M30:$O30)/SQRT(COUNT('Per-Trial Data'!$M30:$O30)),0) | M34: =AVERAGE('Per-Trial Data'!$P30:$R30) | N34: =IF(COUNT('Per-Trial Data'!$P30:$R30)>1,STDEV('Per-Trial Data'!$P30:$R30)/SQRT(COUNT('Per-Trial Data'!$P30:$R30)),0) | O34: =M34-K34 | P34: =SQRT(L34^2+N34^2)
A35: 4WKQ | B35: Gefitinib | C35: EGFR | D35: =AVERAGE('Per-Trial Data'!$D33:$F33) | E35: =AVERAGE('Per-Trial Data'!$G33:$I33) | F35: =IF(COUNT('Per-Trial Data'!$G33:$I33)>1,STDEV('Per-Trial Data'!$G33:$I33)/SQRT(COUNT('Per-Trial Data'!$G33:$I33)),0) | G35: =AVERAGE('Per-Trial Data'!$J33:$L33) | H35: =IF(COUNT('Per-Trial Data'!$J33:$L33)>1,STDEV('Per-Trial Data'!$J33:$L33)/SQRT(COUNT('Per-Trial Data'!$J33:$L33)),0) | I35: =G35-E35 | J35: =SQRT(F35^2+H35^2) | K35: =AVERAGE('Per-Trial Data'!$M33:$O33) | L35: =IF(COUNT('Per-Trial Data'!$M33:$O33)>1,STDEV('Per-Trial Data'!$M33:$O33)/SQRT(COUNT('Per-Trial Data'!$M33:$O33)),0) | M35: =AVERAGE('Per-Trial Data'!$P33:$R33) | N35: =IF(COUNT('Per-Trial Data'!$P33:$R33)>1,STDEV('Per-Trial Data'!$P33:$R33)/SQRT(COUNT('Per-Trial Data'!$P33:$R33)),0) | O35: =M35-K35 | P35: =SQRT(L35^2+N35^2)
A36: 1XKK | B36: Lapatinib | C36: EGFR | D36: =AVERAGE('Per-Trial Data'!$D3:$F3) | E36: =AVERAGE('Per-Trial Data'!$G3:$I3) | F36: =IF(COUNT('Per-Trial Data'!$G3:$I3)>1,STDEV('Per-Trial Data'!$G3:$I3)/SQRT(COUNT('Per-Trial Data'!$G3:$I3)),0) | G36: =AVERAGE('Per-Trial Data'!$J3:$L3) | H36: =IF(COUNT('Per-Trial Data'!$J3:$L3)>1,STDEV('Per-Trial Data'!$J3:$L3)/SQRT(COUNT('Per-Trial Data'!$J3:$L3)),0) | I36: =G36-E36 | J36: =SQRT(F36^2+H36^2) | K36: =AVERAGE('Per-Trial Data'!$M3:$O3) | L36: =IF(COUNT('Per-Trial Data'!$M3:$O3)>1,STDEV('Per-Trial Data'!$M3:$O3)/SQRT(COUNT('Per-Trial Data'!$M3:$O3)),0) | M36: =AVERAGE('Per-Trial Data'!$P3:$R3) | N36: =IF(COUNT('Per-Trial Data'!$P3:$R3)>1,STDEV('Per-Trial Data'!$P3:$R3)/SQRT(COUNT('Per-Trial Data'!$P3:$R3)),0) | O36: =M36-K36 | P36: =SQRT(L36^2+N36^2)
A37: 4ZAU | B37: Osimertinib | C37: EGFR | D37: =AVERAGE('Per-Trial Data'!$D34:$F34) | E37: =AVERAGE('Per-Trial Data'!$G34:$I34) | F37: =IF(COUNT('Per-Trial Data'!$G34:$I34)>1,STDEV('Per-Trial Data'!$G34:$I34)/SQRT(COUNT('Per-Trial Data'!$G34:$I34)),0) | G37: =AVERAGE('Per-Trial Data'!$J34:$L34) | H37: =IF(COUNT('Per-Trial Data'!$J34:$L34)>1,STDEV('Per-Trial Data'!$J34:$L34)/SQRT(COUNT('Per-Trial Data'!$J34:$L34)),0) | I37: =G37-E37 | J37: =SQRT(F37^2+H37^2) | K37: =AVERAGE('Per-Trial Data'!$M34:$O34) | L37: =IF(COUNT('Per-Trial Data'!$M34:$O34)>1,STDEV('Per-Trial Data'!$M34:$O34)/SQRT(COUNT('Per-Trial Data'!$M34:$O34)),0) | M37: =AVERAGE('Per-Trial Data'!$P34:$R34) | N37: =IF(COUNT('Per-Trial Data'!$P34:$R34)>1,STDEV('Per-Trial Data'!$P34:$R34)/SQRT(COUNT('Per-Trial Data'!$P34:$R34)),0) | O37: =M37-K37 | P37: =SQRT(L37^2+N37^2)
B38: JAK3
A39: 3LXK | B39: Tofacitinib | C39: JAK3 | D39: =AVERAGE('Per-Trial Data'!$D14:$F14) | E39: =AVERAGE('Per-Trial Data'!$G14:$I14) | F39: =IF(COUNT('Per-Trial Data'!$G14:$I14)>1,STDEV('Per-Trial Data'!$G14:$I14)/SQRT(COUNT('Per-Trial Data'!$G14:$I14)),0) | G39: =AVERAGE('Per-Trial Data'!$J14:$L14) | H39: =IF(COUNT('Per-Trial Data'!$J14:$L14)>1,STDEV('Per-Trial Data'!$J14:$L14)/SQRT(COUNT('Per-Trial Data'!$J14:$L14)),0) | I39: =G39-E39 | J39: =SQRT(F39^2+H39^2) | K39: =AVERAGE('Per-Trial Data'!$M14:$O14) | L39: =IF(COUNT('Per-Trial Data'!$M14:$O14)>1,STDEV('Per-Trial Data'!$M14:$O14)/SQRT(COUNT('Per-Trial Data'!$M14:$O14)),0) | M39: =AVERAGE('Per-Trial Data'!$P14:$R14) | N39: =IF(COUNT('Per-Trial Data'!$P14:$R14)>1,STDEV('Per-Trial Data'!$P14:$R14)/SQRT(COUNT('Per-Trial Data'!$P14:$R14)),0) | O39: =M39-K39 | P39: =SQRT(L39^2+N39^2)
B40: MEK
A41: 4AN2 | B41: Cobimetinib | C41: MEK | D41: =AVERAGE('Per-Trial Data'!$D24:$F24) | E41: =AVERAGE('Per-Trial Data'!$G24:$I24) | F41: =IF(COUNT('Per-Trial Data'!$G24:$I24)>1,STDEV('Per-Trial Data'!$G24:$I24)/SQRT(COUNT('Per-Trial Data'!$G24:$I24)),0) | G41: =AVERAGE('Per-Trial Data'!$J24:$L24) | H41: =IF(COUNT('Per-Trial Data'!$J24:$L24)>1,STDEV('Per-Trial Data'!$J24:$L24)/SQRT(COUNT('Per-Trial Data'!$J24:$L24)),0) | I41: =G41-E41 | J41: =SQRT(F41^2+H41^2) | K41: =AVERAGE('Per-Trial Data'!$M24:$O24) | L41: =IF(COUNT('Per-Trial Data'!$M24:$O24)>1,STDEV('Per-Trial Data'!$M24:$O24)/SQRT(COUNT('Per-Trial Data'!$M24:$O24)),0) | M41: =AVERAGE('Per-Trial Data'!$P24:$R24) | N41: =IF(COUNT('Per-Trial Data'!$P24:$R24)>1,STDEV('Per-Trial Data'!$P24:$R24)/SQRT(COUNT('Per-Trial Data'!$P24:$R24)),0) | O41: =M41-K41 | P41: =SQRT(L41^2+N41^2)
...

Sheet Per-Trial Conf
E1: P(i) soln | H1: P(i) bound | K1: # rotamers
A2: PDBID | B2: Ligand | C2: Conf type | D2: charge | E2: T01 | F2: T02 | G2: T03 | H2: T01 | I2: T02 | J2: T03 | K2: T01 | L2: T02 | M2: T03
A3: 1XKK | B3: Lapatinib | C3: FMM+1 | D3: 1 | E3: 0.949 | F3: 0.949 | G3: 0.949 | H3: 0.696 | I3: 0.499 | J3: 0.532 | K3: 1 | L3: 1 | M3: 1
A4: 1XKK | B4: Lapatinib | C4: FMM+a | D4: 2 | E4: 0 | F4: 0 | G4: 0 | H4: 0 | I4: 0 | J4: 0 | K4: 1 | L4: 1 | M4: 1
A5: 1XKK | B5: Lapatinib | C5: FMM01 | D5: 0 | E5: 0.051 | F5: 0.051 | G5: 0.051 | H5: 0.304 | I5: 0.501 | J5: 0.468 | K5: 2 | L5: 3 | M5: 2
A6: 2EUF | B6: Palbociclib | C6: LQQ+1 | D6: 1 | E6: 0.975 | F6: 0.975 | G6: 0.975 | H6: 0.999 | I6: 1 | J6: 1 | K6: 1 | L6: 1 | M6: 1
A7: 2EUF | B7: Palbociclib | C7: LQQ01 | D7: 0 | E7: 0.025 | F7: 0.025 | G7: 0.025 | H7: 0.001 | I7: 0 | J7: 0 | K7: 1 | L7: 1 | M7: 1
A8: 2HYY | B8: Imatinib | C8: STI+1 | D8: 1.004 | E8: 0.588 | F8: 0.588 | G8: 0.588 | H8: 0 | I8: 0 | J8: 0.003 | K8: 1 | L8: 1 | M8: 1
A9: 2HYY | B9: Imatinib | C9: STI+2 | D9: 0.995 | E9: 0.38 | F9: 0.38 | G9: 0.38 | H9: 1 | I9: 1 | J9: 0.997 | K9: 1 | L9: 1 | M9: 1
A10: 2HYY | B10: Imatinib | C10: STI+a | D10: 1.995 | E10: 0 | F10: 0 | G10: 0 | H10: 0 | I10: 0 | J10: 0 | K10: 1 | L10: 1 | M10: 1
A11: 2HYY | B11: Imatinib | C11: STI+b | D11: 2.002 | E11: 0 | F11: 0 | G11: 0 | H11: 0 | I11: 0 | J11: 0 | K11: 1 | L11: 1 | M11: 1
A12: 2HYY | B12: Imatinib | C12: STI01 | D12: -0.002 | E12: 0.032 | F12: 0.032 | G12: 0.032 | H12: 0 | I12: 0 | J12: 0 | K12: 1 | L12: 1 | M12: 1
A13: 2ITO | B13: Gefitinib | C13: IRE+1 | D13: 1 | E13: 0.298 | F13: 0.298 | G13: 0.298 | H13: 0.75 | I13: 0.802 | J13: 0.797 | K13: 1 | L13: 1 | M13: 1
A14: 2ITO | B14: Gefitinib | C14: IRE+2 | D14: 1 | E14: 0.002 | F14: 0.002 | G14: 0.002 | H14: 0 | I14: 0 | J14: 0 | K14: 1 | L14: 1 | M14: 1
... A141: 5MO4 | B141: Nilotinib | C141: NIL01 | D141: 0 | E141: 0.907 | F141: 0.907 | G141: 0.907 | H141: 0.769 | I141: 0.775 | J141: 0.753 | K141: 1 | L141: 1 | M141: 1
A143: Occupancy at pH 7.4 from xts_fort.38, summed over the rotamers of each conformer type, per trial. Charge from head3.lst. Types rather than individual rotamers because step2 is stochastic: the rotamer count inside a type varies between trials, so rotamers cannot be matched one-to-one.

Sheet SI-Table2
A1: SI-Table2: ligand conformer populations at pH 7.4, mean of the trials
A2: One row per conformer type (protonation / tautomer state); the rotamers of a type are summed within each trial, then averaged. ± columns are SEM (SD/√n).
A3: RT (kcal/mol) | B3: 0.5925 | C3: energy = -RT·ln(P(i) soln) ; Boltzmann = exp(-energy/RT) ; Stat Mech = Boltzmann / ΣBoltzmann
E5: from P(i) soln | H5: P(i) soln | J5: P(i) bound
A6: PDBID | B6: Ligand | C6: Conf type | D6: charge | E6: energy | F6: Boltzmann Factor | G6: Stat Mech | H6: mean | I6: ± SEM | J6: mean | K6: ± SEM
B7: ABL
A8: 3UE4 | B8: Bosutinib | C8: DB8+1 | D8: ='Per-Trial Conf'!$D52 | E8: =IF(H8>0,-$B$3*LN(H8),"") | F8: =IF(E8="","",EXP(-E8/$B$3)) | G8: =IF(F8="","",F8/SUM(F$8:F$11)) | H8: =AVERAGE('Per-Trial Conf'!$E52:$G52) | I8: =IF(COUNT('Per-Trial Conf'!$E52:$G52)>1,STDEV('Per-Trial Conf'!$E52:$G52)/SQRT(COUNT('Per-Trial Conf'!$E52:$G52)),0) | J8: =AVERAGE('Per-Trial Conf'!$H52:$J52) | K8: =IF(COUNT('Per-Trial Conf'!$H52:$J52)>1,STDEV('Per-Trial Conf'!$H52:$J52)/SQRT(COUNT('Per-Trial Conf'!$H52:$J52)),0)
A9: 3UE4 | B9: Bosutinib | C9: DB8+2 | D9: ='Per-Trial Conf'!$D53 | E9: =IF(H9>0,-$B$3*LN(H9),"") | F9: =IF(E9="","",EXP(-E9/$B$3)) | G9: =IF(F9="","",F9/SUM(F$8:F$11)) | H9: =AVERAGE('Per-Trial Conf'!$E53:$G53) | I9: =IF(COUNT('Per-Trial Conf'!$E53:$G53)>1,STDEV('Per-Trial Conf'!$E53:$G53)/SQRT(COUNT('Per-Trial Conf'!$E53:$G53)),0) | J9: =AVERAGE('Per-Trial Conf'!$H53:$J53) | K9: =IF(COUNT('Per-Trial Conf'!$H53:$J53)>1,STDEV('Per-Trial Conf'!$H53:$J53)/SQRT(COUNT('Per-Trial Conf'!$H53:$J53)),0)
A10: 3UE4 | B10: Bosutinib | C10: DB801 | D10: ='Per-Trial Conf'!$D54 | E10: =IF(H10>0,-$B$3*LN(H10),"") | F10: =IF(E10="","",EXP(-E10/$B$3)) | G10: =IF(F10="","",F10/SUM(F$8:F$11)) | H10: =AVERAGE('Per-Trial Conf'!$E54:$G54) | I10: =IF(COUNT('Per-Trial Conf'!$E54:$G54)>1,STDEV('Per-Trial Conf'!$E54:$G54)/SQRT(COUNT('Per-Trial Conf'!$E54:$G54)),0) | J10: =AVERAGE('Per-Trial Conf'!$H54:$J54) | K10: =IF(COUNT('Per-Trial Conf'!$H54:$J54)>1,STDEV('Per-Trial Conf'!$H54:$J54)/SQRT(COUNT('Per-Trial Conf'!$H54:$J54)),0)
A11: 3UE4 | B11: Bosutinib | C11: DB802 | D11: ='Per-Trial Conf'!$D55 | E11: =IF(H11>0,-$B$3*LN(H11),"") | F11: =IF(E11="","",EXP(-E11/$B$3)) | G11: =IF(F11="","",F11/SUM(F$8:F$11)) | H11: =AVERAGE('Per-Trial Conf'!$E55:$G55) | I11: =IF(COUNT('Per-Trial Conf'!$E55:$G55)>1,STDEV('Per-Trial Conf'!$E55:$G55)/SQRT(COUNT('Per-Trial Conf'!$E55:$G55)),0) | J11: =AVERAGE('Per-Trial Conf'!$H55:$J55) | K11: =IF(COUNT('Per-Trial Conf'!$H55:$J55)>1,STDEV('Per-Trial Conf'!$H55:$J55)/SQRT(COUNT('Per-Trial Conf'!$H55:$J55)),0)
C12: SUM | F12: =SUM(F8:F11) | G12: =SUM(G8:G11) | H12: =SUM(H8:H11) | J12: =SUM(J8:J11)
C13: ensemble charge | G13: =SUMPRODUCT($D8:$D11,G8:G11) | H13: =SUMPRODUCT($D8:$D11,H8:H11) | J13: =SUMPRODUCT($D8:$D11,J8:J11)
A15: 2HYY | B15: Imatinib | C15: STI+1 | D15: ='Per-Trial Conf'!$D8 | E15: =IF(H15>0,-$B$3*LN(H15),"") | F15: =IF(E15="","",EXP(-E15/$B$3)) | G15: =IF(F15="","",F15/SUM(F$15:F$19)) | H15: =AVERAGE('Per-Trial Conf'!$E8:$G8) | I15: =IF(COUNT('Per-Trial Conf'!$E8:$G8)>1,STDEV('Per-Trial Conf'!$E8:$G8)/SQRT(COUNT('Per-Trial Conf'!$E8:$G8)),0) | J15: =AVERAGE('Per-Trial Conf'!$H8:$J8) | K15: =IF(COUNT('Per-Trial Conf'!$H8:$J8)>1,STDEV('Per-Trial Conf'!$H8:$J8)/SQRT(COUNT('Per-Trial Conf'!$H8:$J8)),0)
A16: 2HYY | B16: Imatinib | C16: STI+2 | D16: ='Per-Trial Conf'!$D9 | E16: =IF(H16>0,-$B$3*LN(H16),"") | F16: =IF(E16="","",EXP(-E16/$B$3)) | G16: =IF(F16="","",F16/SUM(F$15:F$19)) | H16: =AVERAGE('Per-Trial Conf'!$E9:$G9) | I16: =IF(COUNT('Per-Trial Conf'!$E9:$G9)>1,STDEV('Per-Trial Conf'!$E9:$G9)/SQRT(COUNT('Per-Trial Conf'!$E9:$G9)),0) | J16: =AVERAGE('Per-Trial Conf'!$H9:$J9) | K16: =IF(COUNT('Per-Trial Conf'!$H9:$J9)>1,STDEV('Per-Trial Conf'!$H9:$J9)/SQRT(COUNT('Per-Trial Conf'!$H9:$J9)),0)
A17: 2HYY | B17: Imatinib | C17: STI+a | D17: ='Per-Trial Conf'!$D10 | E17: =IF(H17>0,-$B$3*LN(H17),"") | F17: =IF(E17="","",EXP(-E17/$B$3)) | G17: =IF(F17="","",F17/SUM(F$15:F$19)) | H17: =AVERAGE('Per-Trial Conf'!$E10:$G10) | I17: =IF(COUNT('Per-Trial Conf'!$E10:$G10)>1,STDEV('Per-Trial Conf'!$E10:$G10)/SQRT(COUNT('Per-Trial Conf'!$E10:$G10)),0) | J17: =AVERAGE('Per-Trial Conf'!$H10:$J10) | K17: =IF(COUNT('Per-Trial Conf'!$H10:$J10)>1,STDEV('Per-Trial Conf'!$H10:$J10)/SQRT(COUNT('Per-Trial Conf'!$H10:$J10)),0)
A18: 2HYY | B18: Imatinib | C18: STI+b | D18: ='Per-Trial Conf'!$D11 | E18: =IF(H18>0,-$B$3*LN(H18),"") | F18: =IF(E18="","",EXP(-E18/$B$3)) | G18: =IF(F18="","",F18/SUM(F$15:F$19)) | H18: =AVERAGE('Per-Trial Conf'!$E11:$G11) | I18: =IF(COUNT('Per-Trial Conf'!$E11:$G11)>1,STDEV('Per-Trial Conf'!$E11:$G11)/SQRT(COUNT('Per-Trial Conf'!$E11:$G11)),0) | J18: =AVERAGE('Per-Trial Conf'!$H11:$J11) | K18: =IF(COUNT('Per-Trial Conf'!$H11:$J11)>1,STDEV('Per-Trial Conf'!$H11:$J11)/SQRT(COUNT('Per-Trial Conf'!$H11:$J11)),0)
A19: 2HYY | B19: Imatinib | C19: STI01 | D19: ='Per-Trial Conf'!$D12 | E19: =IF(H19>0,-$B$3*LN(H19),"") | F19: =IF(E19="","",EXP(-E19/$B$3)) | G19: =IF(F19="","",F19/SUM(F$15:F$19)) | H19: =AVERAGE('Per-Trial Conf'!$E12:$G12) | I19: =IF(COUNT('Per-Trial Conf'!$E12:$G12)>1,STDEV('Per-Trial Conf'!$E12:$G12)/SQRT(COUNT('Per-Trial Conf'!$E12:$G12)),0) | J19: =AVERAGE('Per-Trial Conf'!$H12:$J12) | K19: =IF(COUNT('Per-Trial Conf'!$H12:$J12)>1,STDEV('Per-Trial Conf'!$H12:$J12)/SQRT(COUNT('Per-Trial Conf'!$H12:$J12)),0)
C20: SUM | F20: =SUM(F15:F19) | G20: =SUM(G15:G19) | H20: =SUM(H15:H19) | J20: =SUM(J15:J19)
C21: ensemble charge | G21: =SUMPRODUCT($D15:$D19,G15:G19) | H21: =SUMPRODUCT($D15:$D19,H15:H19) | J21: =SUMPRODUCT($D15:$D19,J15:J19)
A23: 3PYY | B23: Imatinib | C23: STI+1 | D23: ='Per-Trial Conf'!$D47 | E23: =IF(H23>0,-$B$3*LN(H23),"") | F23: =IF(E23="","",EXP(-E23/$B$3)) | G23: =IF(F23="","",F23/SUM(F$23:F$27)) | H23: =AVERAGE('Per-Trial Conf'!$E47:$G47) | I23: =IF(COUNT('Per-Trial Conf'!$E47:$G47)>1,STDEV('Per-Trial Conf'!$E47:$G47)/SQRT(COUNT('Per-Trial Conf'!$E47:$G47)),0) | J23: =AVERAGE('Per-Trial Conf'!$H47:$J47) | K23: =IF(COUNT('Per-Trial Conf'!$H47:$J47)>1,STDEV('Per-Trial Conf'!$H47:$J47)/SQRT(COUNT('Per-Trial Conf'!$H47:$J47)),0)
A24: 3PYY | B24: Imatinib | C24: STI+2 | D24: ='Per-Trial Conf'!$D48 | E24: =IF(H24>0,-$B$3*LN(H24),"") | F24: =IF(E24="","",EXP(-E24/$B$3)) | G24: =IF(F24="","",F24/SUM(F$23:F$27)) | H24: =AVERAGE('Per-Trial Conf'!$E48:$G48) | I24: =IF(COUNT('Per-Trial Conf'!$E48:$G48)>1,STDEV('Per-Trial Conf'!$E48:$G48)/SQRT(COUNT('Per-Trial Conf'!$E48:$G48)),0) | J24: =AVERAGE('Per-Trial Conf'!$H48:$J48) | K24: =IF(COUNT('Per-Trial Conf'!$H48:$J48)>1,STDEV('Per-Trial Conf'!$H48:$J48)/SQRT(COUNT('Per-Trial Conf'!$H48:$J48)),0)
A25: 3PYY | B25: Imatinib | C25: STI+a | D25: ='Per-Trial Conf'!$D49 | E25: =IF(H25>0,-$B$3*LN(H25),"") | F25: =IF(E25="","",EXP(-E25/$B$3)) | G25: =IF(F25="","",F25/SUM(F$23:F$27)) | H25: =AVERAGE('Per-Trial Conf'!$E49:$G49) | I25: =IF(COUNT('Per-Trial Conf'!$E49:$G49)>1,STDEV('Per-Trial Conf'!$E49:$G49)/SQRT(COUNT('Per-Trial Conf'!$E49:$G49)),0) | J25: =AVERAGE('Per-Trial Conf'!$H49:$J49) | K25: =IF(COUNT('Per-Trial Conf'!$H49:$J49)>1,STDEV('Per-Trial Conf'!$H49:$J49)/SQRT(COUNT('Per-Trial Conf'!$H49:$J49)),0)
A26: 3PYY | B26: Imatinib | C26: STI+b | D26: ='Per-Trial Conf'!$D50 | E26: =IF(H26>0,-$B$3*LN(H26),"") | F26: =IF(E26="","",EXP(-E26/$B$3)) | G26: =IF(F26="","",F26/SUM(F$23:F$27)) | H26: =AVERAGE('Per-Trial Conf'!$E50:$G50) | I26: =IF(COUNT('Per-Trial Conf'!$E50:$G50)>1,STDEV('Per-Trial Conf'!$E50:$G50)/SQRT(COUNT('Per-Trial Conf'!$E50:$G50)),0) | J26: =AVERAGE('Per-Trial Conf'!$H50:$J50) | K26: =IF(COUNT('Per-Trial Conf'!$H50:$J50)>1,STDEV('Per-Trial Conf'!$H50:$J50)/SQRT(COUNT('Per-Trial Conf'!$H50:$J50)),0)
A27: 3PYY | B27: Imatinib | C27: STI01 | D27: ='Per-Trial Conf'!$D51 | E27: =IF(H27>0,-$B$3*LN(H27),"") | F27: =IF(E27="","",EXP(-E27/$B$3)) | G27: =IF(F27="","",F27/SUM(F$23:F$27)) | H27: =AVERAGE('Per-Trial Conf'!$E51:$G51) | I27: =IF(COUNT('Per-Trial Conf'!$E51:$G51)>1,STDEV('Per-Trial Conf'!$E51:$G51)/SQRT(COUNT('Per-Trial Conf'!$E51:$G51)),0) | J27: =AVERAGE('Per-Trial Conf'!$H51:$J51) | K27: =IF(COUNT('Per-Trial Conf'!$H51:$J51)>1,STDEV('Per-Trial Conf'!$H51:$J51)/SQRT(COUNT('Per-Trial Conf'!$H51:$J51)),0)
C28: SUM | F28: =SUM(F23:F27) | G28: =SUM(G23:G27) | H28: =SUM(H23:H27) | J28: =SUM(J23:J27)
C29: ensemble charge | G29: =SUMPRODUCT($D23:$D27,G23:G27) | H29: =SUMPRODUCT($D23:$D27,H23:H27) | J29: =SUMPRODUCT($D23:$D27,J23:J27)
A31: 3CS9 | B31: Nilotinib | C31: NIL+1 | D31: ='Per-Trial Conf'!$D42 | E31: =IF(H31>0,-$B$3*LN(H31),"") | F31: =IF(E31="","",EXP(-E31/$B$3)) | G31: =IF(F31="","",F31/SUM(F$31:F$33)) | H31: =AVERAGE('Per-Trial Conf'!$E42:$G42) | I31: =IF(COUNT('Per-Trial Conf'!$E42:$G42)>1,STDEV('Per-Trial Conf'!$E42:$G42)/SQRT(COUNT('Per-Trial Conf'!$E42:$G42)),0) | J31: =AVERAGE('Per-Trial Conf'!$H42:$J42) | K31: =IF(COUNT('Per-Trial Conf'!$H42:$J42)>1,STDEV('Per-Trial Conf'!$H42:$J42)/SQRT(COUNT('Per-Trial Conf'!$H42:$J42)),0)
A32: 3CS9 | B32: Nilotinib | C32: NIL+2 | D32: ='Per-Trial Conf'!$D43 | E32: =IF(H32>0,-$B$3*LN(H32),"") | F32: =IF(E32="","",EXP(-E32/$B$3)) | G32: =IF(F32="","",F32/SUM(F$31:F$33)) | H32: =AVERAGE('Per-Trial Conf'!$E43:$G43) | I32: =IF(COUNT('Per-Trial Conf'!$E43:$G43)>1,STDEV('Per-Trial Conf'!$E43:$G43)/SQRT(COUNT('Per-Trial Conf'!$E43:$G43)),0) | J32: =AVERAGE('Per-Trial Conf'!$H43:$J43) | K32: =IF(COUNT('Per-Trial Conf'!$H43:$J43)>1,STDEV('Per-Trial Conf'!$H43:$J43)/SQRT(COUNT('Per-Trial Conf'!$H43:$J43)),0)
A33: 3CS9 | B33: Nilotinib | C33: NIL01 | D33: ='Per-Trial Conf'!$D44 | E33: =IF(H33>0,-$B$3*LN(H33),"") | F33: =IF(E33="","",EXP(-E33/$B$3)) | G33: =IF(F33="","",F33/SUM(F$31:F$33)) | H33: =AVERAGE('Per-Trial Conf'!$E44:$G44) | I33: =IF(COUNT('Per-Trial Conf'!$E44:$G44)>1,STDEV('Per-Trial Conf'!$E44:$G44)/SQRT(COUNT('Per-Trial Conf'!$E44:$G44)),0) | J33: =AVERAGE('Per-Trial Conf'!$H44:$J44) | K33: =IF(COUNT('Per-Trial Conf'!$H44:$J44)>1,STDEV('Per-Trial Conf'!$H44:$J44)/SQRT(COUNT('Per-Trial Conf'!$H44:$J44)),0)
C34: SUM | F34: =SUM(F31:F33) | G34: =SUM(G31:G33) | H34: =SUM(H31:H33) | J34: =SUM(J31:J33)
C35: ensemble charge | G35: =SUMPRODUCT($D31:$D33,G31:G33) | H35: =SUMPRODUCT($D31:$D33,H31:H33) | J35: =SUMPRODUCT($D31:$D33,J31:J33)
A37: 5MO4 | B37: Nilotinib | C37: NIL+1 | D37: ='Per-Trial Conf'!$D139 | E37: =IF(H37>0,-$B$3*LN(H37),"") | F37: =IF(E37="","",EXP(-E37/$B$3)) | G37: =IF(F37="","",F37/SUM(F$37:F$39)) | H37: =AVERAGE('Per-Trial Conf'!$E139:$G139) | I37: =IF(COUNT('Per-Trial Conf'!$E139:$G139)>1,STDEV('Per-Trial Conf'!$E139:$G139)/SQRT(COUNT('Per-Trial Conf'!$E139:$G139)),0) | J37: =AVERAGE('Per-Trial Conf'!$H139:$J139) | K37: =IF(COUNT('Per-Trial Conf'!$H139:$J139)>1,STDEV('Per-Trial Conf'!$H139:$J139)/SQRT(COUNT('Per-Trial Conf'!$H139:$J139)),0)
A38: 5MO4 | B38: Nilotinib | C38: NIL+2 | D38: ='Per-Trial Conf'!$D140 | E38: =IF(H38>0,-$B$3*LN(H38),"") | F38: =IF(E38="","",EXP(-E38/$B$3)) | G38: =IF(F38="","",F38/SUM(F$37:F$39)) | H38: =AVERAGE('Per-Trial Conf'!$E140:$G140) | I38: =IF(COUNT('Per-Trial Conf'!$E140:$G140)>1,STDEV('Per-Trial Conf'!$E140:$G140)/SQRT(COUNT('Per-Trial Conf'!$E140:$G140)),0) | J38: =AVERAGE('Per-Trial Conf'!$H140:$J140) | K38: =IF(COUNT('Per-Trial Conf'!$H140:$J140)>1,STDEV('Per-Trial Conf'!$H140:$J140)/SQRT(COUNT('Per-Trial Conf'!$H140:$J140)),0)
A39: 5MO4 | B39: Nilotinib | C39: NIL01 | D39: ='Per-Trial Conf'!$D141 | E39: =IF(H39>0,-$B$3*LN(H39),"") | F39: =IF(E39="","",EXP(-E39/$B$3)) | G39: =IF(F39="","",F39/SUM(F$37:F$39)) | H39: =AVERAGE('Per-Trial Conf'!$E141:$G141) | I39: =IF(COUNT('Per-Trial Conf'!$E141:$G141)>1,STDEV('Per-Trial Conf'!$E141:$G141)/SQRT(COUNT('Per-Trial Conf'!$E141:$G141)),0) | J39: =AVERAGE('Per-Trial Conf'!$H141:$J141) | K39: =IF(COUNT('Per-Trial Conf'!$H141:$J141)>1,STDEV('Per-Trial Conf'!$H141:$J141)/SQRT(COUNT('Per-Trial Conf'!$H141:$J141)),0)
C40: SUM | F40: =SUM(F37:F39) | G40: =SUM(G37:G39) | H40: =SUM(H37:H39) | J40: =SUM(J37:J39)
C41: ensemble charge | G41: =SUMPRODUCT($D37:$D39,G37:G39) | H41: =SUMPRODUCT($D37:$D39,H37:H39) | J41: =SUMPRODUCT($D37:$D39,J37:J39)
B43: ALK
A44: 3AOX | B44: Alectinib | C44: EMH+1 | D44: ='Per-Trial Conf'!$D40 | E44: =IF(H44>0,-$B$3*LN(H44),"") | F44: =IF(E44="","",EXP(-E44/$B$3)) | G44: =IF(F44="","",F44/SUM(F$44:F$45)) | H44: =AVERAGE('Per-Trial Conf'!$E40:$G40) | I44: =IF(COUNT('Per-Trial Conf'!$E40:$G40)>1,STDEV('Per-Trial Conf'!$E40:$G40)/SQRT(COUNT('Per-Trial Conf'!$E40:$G40)),0) | J44: =AVERAGE('Per-Trial Conf'!$H40:$J40) | K44: =IF(COUNT('Per-Trial Conf'!$H40:$J40)>1,STDEV('Per-Trial Conf'!$H40:$J40)/SQRT(COUNT('Per-Trial Conf'!$H40:$J40)),0)
A45: 3AOX | B45: Alectinib | C45: EMH01 | D45: ='Per-Trial Conf'!$D41 | E45: =IF(H45>0,-$B$3*LN(H45),"") | F45: =IF(E45="","",EXP(-E45/$B$3)) | G45: =IF(F45="","",F45/SUM(F$44:F$45)) | H45: =AVERAGE('Per-Trial Conf'!$E41:$G41) | I45: =IF(COUNT('Per-Trial Conf'!$E41:$G41)>1,STDEV('Per-Trial Conf'!$E41:$G41)/SQRT(COUNT('Per-Trial Conf'!$E41:$G41)),0) | J45: =AVERAGE('Per-Trial Conf'!$H41:$J41) | K45: =IF(COUNT('Per-Trial Conf'!$H41:$J41)>1,STDEV('Per-Trial Conf'!$H41:$J41)/SQRT(COUNT('Per-Trial Conf'!$H41:$J41)),0)
C46: SUM | F46: =SUM(F44:F45) | G46: =SUM(G44:G45) | H46: =SUM(H44:H45) | J46: =SUM(J44:J45)
...

Sheet Methods
A1: Methods: how the Trials statistics were computed
A2: Generated 2026-09-22 23:36:02 by make_trials_tables_xlsx.py
A4: Replicates
A5: n | B5: 3 independent trials of the full MCCE4 pipeline (steps 1-4)
A6: Trial01 | B6: MONTE_SEED = 1001
A7: Trial02 | B7: MONTE_SEED = 1002
A8: Trial03 | B8: MONTE_SEED = 1003
A9: What varies | B9: step2 rotamer generation does not reproduce between runs, so each trial has its own conformer set, and step4 Monte Carlo uses a per-trial seed. A trial is therefore the replicate unit: re-running step4 alone in a finished tree would hold the conformers fixed and understate the spread.
A11: Statistics
A12: mean | B12: arithmetic mean over the n trials
A13: SD | B13: sample standard deviation (n-1 denominator)
A14: SEM | B14: SD / √n — every ± column, and the plotted error bar
A15: ∆crg (Table 1) | B15: difference of the trial means; ± is the propagated SEM √(a²+b²)
A16: ∆q (per residue) | B16: holo − apo computed WITHIN each trial, then averaged. apo reuses holo's conformers inside a trial, so the pairing cancels the conformer set; combining two independent SEMs would overstate the error.
A18: Caveat | B18: Error bars are ±1 SEM, NOT a confidence interval. With n=3 there are 2 degrees of freedom, so a 95% CI would be mean ± 4.30 × SEM.
A19: Scope | B19: The spread reflects run-to-run reproducibility of the pipeline. It does not include force-field, dielectric (ε=4) or crystal-structure uncertainty.
A21: Provenance
A22: Charges | B22: xts_sum_crg.out at pH 7.4 — the entropy-corrected output of xts_corr.py, which step4 does not produce on its own
A23: Ligand #conf | B23: conformer count for the ligand in run_inhib/head3.lst
A24: Kinase | B24: the Kinase column of pdb_inhibitor.lst

Sheet Outliers (holo-apo)
A1: Tier | B1: PDB | C1: Inhibitor | D1: ResName | E1: Chain | F1: ResNum | G1: Residue | H1: ApoCharge | I1: HoloCharge | J1: DeltaCharge | K1: DeltaSEM | L1: DeltaMin | M1: DeltaMax | N1: Reproducible
A2: strong | B2: 4MKC | C2: Ceritinib | D2: LYS | E2: A | F2: 1205 | G2: LYS+A1205 | H2: 0.663 | I2: 0.153 | J2: -0.51 | K2: 0 | L2: -0.51 | M2: -0.51 | N2: yes
A3: affected | B3: 1XKK | C3: Lapatinib | D3: LYS | E3: A | F3: 745 | G3: LYS+A0745 | H3: 0.887 | I3: 0.49 | J3: -0.397 | K3: 0.022 | L3: -0.44 | M3: -0.37 | N3: yes
A4: affected | B4: 1XKK | C4: Lapatinib | D4: CYS | E4: A | F4: 775 | G4: CYS-A0775 | H4: -0.263 | I4: 0 | J4: 0.263 | K4: 0.037 | L4: 0.19 | M4: 0.3 | N4: NO
A5: affected | B5: 3UE4 | C5: Bosutinib | D5: GLU | E5: A | F5: 286 | G5: GLU-A0286 | H5: -0.307 | I5: -0.557 | J5: -0.25 | K5: 0.012 | L5: -0.27 | M5: -0.23 | N5: yes
A6: affected | B6: 4AN2 | C6: Cobimetinib | D6: CYS | E6: A | F6: 207 | G6: CYS-A0207 | H6: -0.74 | I6: -0.97 | J6: -0.23 | K6: 0.006 | L6: -0.24 | M6: -0.22 | N6: yes
A8: Reproducible = every trial clears the tier threshold. 'NO' means the classification depends on which trial you look at.

Sheet Reproducibility
A1: Is the mean a fair summary of the trials?
A3: Fig4A — per residue (holo vs apo)
A4: Category | B4: N | C4: Percent | D4: Meaning
A5: identical | B5: 3179 | C5: 86.7 | D5: all trials gave the same value; SEM is exactly 0
A6: scattered | B6: 488 | C6: 13.3 | D6: unimodal spread; mean +/- SEM is a fair summary
A7: two-state | B7: 1 | C7: 0 | D7: discrete bistability; the mean is a value never sampled
A9: # points NOT summarised well by mean +/- SEM
A10: Key | B10: PerTrial | C10: Range
A11: 4I22/HIS+A0850_ | B11: -0.13;-0.27;-0.19 | C11: 0.14
A12: 1XKK/LYS+A0852_ | B12: -0.22;-0.10;-0.21 | C12: 0.12
A13: 1XKK/CYS-A0775_ | B13: +0.30;+0.19;+0.30 | C13: 0.11
A14: 4I22/HIS+A0773_ | B14: +0.13;+0.21;+0.15 | C14: 0.08
A15: 1XKK/LYS+A0745_ | B15: -0.44;-0.38;-0.37 | C15: 0.07
A16: 5L2I/ASP-A0163_ | B16: +0.13;+0.06;+0.07 | C16: 0.07
A17: 4AGD/ASP-A0809_ | B17: +0.02;+0.00;-0.03 | C17: 0.05
A19: Fig3 — per inhibitor (bound vs solution)
A20: Category | B20: N | C20: Percent | D20: Meaning
A21: identical | B21: 22 | C21: 59.5 | D21: all trials gave the same value; SEM is exactly 0
A22: scattered | B22: 13 | C22: 35.1 | D22: unimodal spread; mean +/- SEM is a fair summary
A23: two-state | B23: 2 | C23: 5.4 | D23: discrete bistability; the mean is a value never sampled
A25: # points NOT summarised well by mean +/- SEM
A26: Key | B26: PerTrial | C26: Range
A27: 3CS9 | B27: +0.42;+0.63;+0.19 | C27: 0.44
A28: 1XKK | B28: +0.70;+0.50;+0.53 | C28: 0.2
A29: 3AOX | B29: +0.79;+0.90;+0.79 | C29: 0.11
A30: 4WKQ | B30: +0.43;+0.49;+0.47 | C30: 0.06
A31: 2ITO | B31: +0.75;+0.80;+0.80 | C31: 0.05
